Workbook
Name MarineSuperintendent: Guide!$A$35:$A$51
Name MS: Guide!$A$35:$A$37
Name Place: Guide!$A$39:$A$39
Name Superintendent: Guide!$A$35:$A$37
Name VisitPlace: Guide!$A$52:$A$53

Sheet Guide
A1: Guideline to use this folder
A3: In the sheets "IA-SI TANKER" and "IA-SI DRY":
B4: Insert only the date in which Internal Audit and Safety Inspection are carried out
B5: Expiring dates will be calculated authomatically in order to produce the schedule/Plan according to the below legend
B6: l Black light = current date > anniversay date + 90 days
B7: l Red light = anniversary date < current date < anniversary date + 90 days
B8: l Yellow light = anniversay date - 30 days < current day < anniversay date
B9: l Green light = current date < anniversay date - 30 days
A11: In the sheets "TANKER DATA" and "DRY DATA":
B12: For each vessel are available 4 raws. Each raw must be dedicated to one visit on board, during which one or more kind of audits/inspections can be carried out
B13: · Select Superintendent and place through the drop down menu
B14: · Insert for each inspection/Audit, the date of execution, the date of report (date in which the report is ulpoaded into Shipnet or officially delivered to the vessel) and the nr. of NC and observations. Total remarks are calculaed automatically.
B15: The date could also be a period from-to
B16: · Insert the date of training if carried out (it could be also a period from-to)
B17: · Insert the date of vetting and the name of vetting Company if carried out
B18: · Complete witht Travel's informations as departure/return dates, boarding/disembarking dates, and total days
A20: In the sheets "Int. Aud. Category" and "Saf Insp. Category":
B21: · For each vessel, after an inspection, insert or update the number of inspections (increasing of 1),
B22: and insert or update the deficiencies raised, as per Sire categories, according to the quarter in which the inspections carried out
A24: In the sheet "Nav. Audit Comparison "
B25: · For each vessel, insert or update the number of observation raised by Master during navigation audit in the box Navigation Audit Remarks by Master, according to the quarter in which the inspections carried out
A29: All other Sheets are automated and must not be touched
A35: Manpreet
A36: Ashwin
A37: Venster
A38: Naveen
A39: Maqsood
A40: Avish
A41: Amandeep
A42: Ankur
A43: Jay
A44: Siddharth
A45: Kaustubh
... A56: R

Sheet IA Planner
A1: VISIT PLANNER FOR 2024
A2: Note:
B3: Planning Month for Marine Visit | E3: xx | G3: Due Date for Marine Visit | L3: Done and next due is next year
B4: Planning Month for Technical Visit | E4: xx | G4: Due Date for Technial Visit | L4: Done and next due is next year
A5: Sr. No. | B5: Vessel Name | C5: Jan | E5: Feb | G5: Mar | H5: Apr | J5: May | K5: June | L5: July | M5: Aug | N5: Sept | O5: Oct | Q5: Nov | R5: Dec
A6: 1 | B6: BAGHEERA | C6: 1 | H6: 17 | L6: 1
A7: 2 | B7: BANTRY BAY | L7: 22 | M7: 22
A8: 3 | B8: BRIGHT FUTURE | E8: 24 | K8: 20 | M8: 24
A9: 4 | B9: CIELO DI HOUSTON | C9: 8 | D9: 18 | L9: 21
A10: 5 | B10: CIELO ROSSO | H10: 1 | J10: 11 | O10: 1
A11: 6 | B11: CLEAROCEAN MARIA | H11: 29 | N11: 20 | O11: 27
A12: 7 | B12: CLEAROCEAN MARY | J12: 7 | Q12: 22 | R12: 21
A13: 8 | B13: CLEAROCEAN MATHILDE | G13: 16 | L13: 23 | N13: 15
A14: 9 | B14: CLEAROCEAN MUSIC | H14: 1 | M14: 27 | N14: 30
A15: 10 | B15: RUI FU XING (ex GLENDA MELANIE) | C15: 31 | J15: 14 | L15: 31
A16: 11 | B16: GLENDA MELISSA | E16: 1 | M16: 14
A17: 12 | B17: GLENDA MELODY | H17: 15 | I17: 14 | O17: 13
A18: 13 | B18: GLENDA MERYL | C18: 2 | D18: 18 | J18: 18 | Q18: 17
A19: 14 | B19: HEROLDS BAY | L19: 9 | N19: 29
A20: 15 | B20: HIGH EXPLORER | C20: 28 | L20: 28 | M20: 27
A21: 16 | B21: HIGH TRANSPORTER | C21: 28 | L21: 26 | M21: 3
A22: 17 | B22: KALK BAY | H22: 22 | K22: 7
A23: 18 | B23: MOSSEL BAY | C23: 2 | G23: 23 | L23: 6
A24: 19 | B24: PHILOTIMOS | L24: 25
A25: 20 | B25: PHILOXENIA | C25: 8 | E25: 21 | J25: 7 | O25: 5
A26: 21 | B26: PNX CONQUEROR | E26: 8 | G26: 10
A27: 22 | B27: PS TOKYO | E27: 6 | F27: 7
A28: 23 | B28: PS VANCOUVER | K28: 1 | O28: 19 | R28: 30
A29: 24 | B29: RUI FU SHENG | K29: 7 | L29: 23
A30: 25 | B30: TABLE BAY | E30: 26 | K30: 18 | M30: 30
A31: 26 | B31: VIALLI | C31: 14 | K31: 1
A32: 27 | B32: VICTORIA BAY | G32: 1 | K32: 22 | N32: 2
A33: 28 | B33: CIELO DEI MARONTI | J33: 9 | M33: 7
A34: 29 | B34: CIELO DI VALPARAISO | G34: 14
A35: 30 | B35: MEDI ADRIATICO | C35: 5 | L35: 7
A36: 31 | B36: MEDI ATLANTICO | E36: 18 | K36: 16 | M36: 18
A37: 32 | B37: MEDI CABOTO
A38: 32 | B38: MEDI EGADI | H38: 23 | L38: 9
A39: 33 | B39: MEDI EGEO | K39: 1 | N39: 25
A40: 34 | B40: MEDI PALMAROLA | H40: 28 | M40: 24
...

Sheet  IA-SI DRY
D1: Internal Audit / Inspection Scheduling-Plan
B2: =TODAY() -> 45805 | D2: Internal Audit | H2: Safety Inspection | L2: Technical Inspection
C3: Superintendent | D3: Status | E3: Last Audit date | F3: Remote | G3: Expiring Audit date | H3: Status | I3: Last Inspection date | J3: Remote | K3: Expiring Inspection date | L3: Status | M3: Last Inspection date | N3: Remote | O3: Expiring Inspection date | P3: Status validity for 6 Months
B4: Cielo di Valparaiso | C4: Maqsood | D4: =DAYS360(E4,TODAY()) -> 558 | E4: 45240 | G4: =EDATE(E4,12) -> 45606 | H4: =DAYS360(I4,TODAY()) -> 558 | I4: 45240 | K4: =EDATE(I4,12) -> 45606 | L4: =DAYS360(M4,TODAY()) -> 996 | M4: 44795 | O4: =EDATE(M4,6) -> 44979 | P4: {=DAYS180(E4,I4,M4,TODAY())} -> #NAME?
B5: Cielo Dei Maronti | C5: Naveen | D5: =DAYS360(E5,TODAY()) -> 291 | E5: 45511 | G5: =EDATE(E5,12) -> 45876 | H5: =DAYS360(I5,TODAY()) -> 676 | I5: 45119 | K5: =EDATE(I5,12) -> 45485 | L5: =DAYS360(M5,TODAY()) -> 835 | M5: 44960 | O5: =EDATE(M5,6) -> 45141 | P5: =DAYS360(Q5,TODAY()) -> 45148
B6: Medi Adriatico | C6: Avish | D6: =DAYS360(E6,TODAY()) -> 296 | E6: 45506 | G6: =EDATE(E6,12) -> 45871 | H6: =DAYS360(I6,TODAY()) -> 296 | I6: 45506 | K6: =EDATE(I6,12) -> 45871 | L6: =DAYS360(M6,TODAY()) -> 984 | M6: 44808 | N6: R | O6: =EDATE(M6,6) -> 44989 | P6: =DAYS360(Q6,TODAY()) -> 45148
B7: Medi Atlantico | C7: Naveen | D7: =DAYS360(E7,TODAY()) -> 332 | E7: 45469 | G7: =EDATE(E7,12) -> 45834 | H7: =DAYS360(I7,TODAY()) -> 702 | I7: 45093 | K7: =EDATE(I7,12) -> 45459 | L7: =DAYS360(M7,TODAY()) -> 865 | M7: 44929 | O7: =EDATE(M7,6) -> 45110 | P7: =DAYS360(Q7,TODAY()) -> 45148
B8: Medi Egadi | C8: Naveen | D8: =DAYS360(E8,TODAY()) -> 290 | E8: 45512 | G8: =EDATE(E8,12) -> 45877 | H8: =DAYS360(I8,TODAY()) -> 679 | I8: 45116 | K8: =EDATE(I8,12) -> 45482 | L8: =DAYS360(M8,TODAY()) -> 912 | M8: 44881 | O8: =EDATE(M8,6) -> 45062 | P8: =DAYS360(Q8,TODAY()) -> 45148
B9: Medi Egeo | C9: Naveen | D9: =DAYS360(E9,TODAY()) -> 238 | E9: 45565 | G9: =EDATE(E9,12) -> 45930 | H9: =DAYS360(I9,TODAY()) -> 603 | I9: 45194 | K9: =EDATE(I9,12) -> 45560 | L9: =DAYS360(M9,TODAY()) -> 784 | M9: 45009 | O9: =EDATE(M9,6) -> 45193 | P9: =DAYS360(Q9,TODAY()) -> 45148
B10: Medi Matsuura | C10: Naveen | D10: =DAYS360(E10,TODAY()) -> 208 | E10: 45595 | G10: =EDATE(E10,12) -> 45960 | H10: =DAYS360(I10,TODAY()) -> 208 | I10: 45595 | K10: =EDATE(I10,12) -> 45960
B11: Medi Palmarola | C11: Gaurav | D11: =DAYS360(E11,TODAY()) -> 300 | E11: 45501 | G11: =EDATE(E11,12) -> 45866 | H11: =DAYS360(I11,TODAY()) -> 300 | I11: 45501 | K11: =EDATE(I11,12) -> 45866 | L11: =DAYS360(M11,TODAY()) -> 959 | M11: 44833 | O11: =EDATE(M11,6) -> 45014 | P11: =DAYS360(Q11,TODAY()) -> 45148
B12: Medi Sydney | C12: Siddharth | D12: =DAYS360(E12,TODAY()) -> 232 | E12: 45571 | G12: =EDATE(E12,12) -> 45936 | H12: =DAYS360(I12,TODAY()) -> 232 | I12: 45571 | K12: =EDATE(I12,12) -> 45936 | M12: 45571
B13: Medi Tirreno | C13: Avish | D13: =DAYS360(E13,TODAY()) -> 507 | E13: 45292 | G13: =EDATE(E13,12) -> 45658 | H13: =DAYS360(I13,TODAY()) -> 847 | I13: 44947 | K13: =EDATE(I13,12) -> 45312 | L13: =DAYS360(M13,TODAY()) -> 1089 | M13: 44700 | O13: =EDATE(M13,6) -> 44884 | P13: =DAYS360(Q13,TODAY()) -> 45148
B14: Medi Zuoz | C14: Avish | D14: =DAYS360(E14,TODAY()) -> 273 | E14: 45529 | G14: =EDATE(E14,12) -> 45894 | H14: =DAYS360(I14,TODAY()) -> 273 | I14: 45529 | K14: =EDATE(I14,12) -> 45894 | L14: =DAYS360(M14,TODAY()) -> 878 | M14: 44915 | O14: =EDATE(M14,6) -> 45097 | P14: =DAYS360(Q14,TODAY()) -> 45148
B15: Medi Caboto | D15: =DAYS360(E15,TODAY()) -> 45148 | H15: =DAYS360(I15,TODAY()) -> 45148 | L15: =DAYS360(M15,TODAY()) -> 45148 | P15: =DAYS360(Q15,TODAY()) -> 45148

Sheet IA-SI  TANKER
D1: Internal Audit / Inspection Scheduling-Plan
B2: =TODAY() -> 45805 | D2: Internal Audit | H2: Safety Inspection | L2: Technical Inspection
C3: Superintendent | D3: Status | E3: Last Audit date | F3: Remote | G3: Expiring Audit date | H3: Status | I3: Last Inspection date | J3: Remote | K3: Expiring Inspection date | L3: Status | M3: Last Inspection date | N3: Remote | O3: Expiring Inspection date | P3: Status validity for 6 Months
B4: Alpine Pembroke (Sold) | C4: Maqsood | D4: =DAYS360(E4,TODAY()) -> 852 | E4: 44942 | G4: =EDATE(E4,12) -> 45307 | H4: =DAYS360(I4,TODAY()) -> 726 | I4: 45068 | K4: =EDATE(I4,12) -> 45434 | L4: =DAYS360(M4,TODAY()) -> 45148 | O4: =EDATE(M4,6) -> 182 | P4: =DAYS360(O4,TODAY()) -> 44968
B5: Alpine Pioneer (Sold) | C5: Venster | D5: =DAYS360(E5,TODAY()) -> 670 | E5: 45125 | G5: =EDATE(E5,12) -> 45491 | H5: =DAYS360(I5,TODAY()) -> 670 | I5: 45125 | K5: =EDATE(I5,12) -> 45491 | L5: =DAYS360(M5,TODAY()) -> 45148 | O5: =EDATE(M5,6) -> 182 | P5: =DAYS360(O5,TODAY()) -> 44968
B6: Bagheera | C6: Naveen | D6: =DAYS360(E6,TODAY()) -> 387 | E6: 45413 | G6: =EDATE(E6,12) -> 45778 | H6: =DAYS360(I6,TODAY()) -> 387 | I6: 45413 | K6: =EDATE(I6,12) -> 45778 | L6: =DAYS360(M6,TODAY()) -> 323 | M6: 45478 | O6: =EDATE(M6,6) -> 45662 | P6: =DAYS360(O6,TODAY()) -> 143
B7: Bantry Bay | C7: Rajneesh | D7: =DAYS360(E7,TODAY()) -> 276 | E7: 45526 | G7: =EDATE(E7,12) -> 45891 | H7: =DAYS360(I7,TODAY()) -> 276 | I7: 45526 | L7: =DAYS360(M7,TODAY()) -> 304 | M7: 45497 | O7: =EDATE(M7,6) -> 45681 | P7: =DAYS360(O7,TODAY()) -> 124
B8: Bright Future | C8: Ashwin | D8: =DAYS360(E8,TODAY()) -> 335 | E8: 45466 | G8: =EDATE(E8,12) -> 45831 | H8: =DAYS360(I8,TODAY()) -> 335 | I8: 45466 | K8: =EDATE(I8,12) -> 45831 | L8: =DAYS360(M8,TODAY()) -> 450 | M8: 45350 | O8: =EDATE(M8,6) -> 45532 | P8: =DAYS360(O8,TODAY()) -> 270
B9: Cielo di Houston | C9: Naveen | D9: =DAYS360(E9,TODAY()) -> 229 | E9: 45574 | G9: =EDATE(E9,12) -> 45939 | H9: =DAYS360(I9,TODAY()) -> 229 | I9: 45574 | K9: =EDATE(I9,12) -> 45939 | L9: =DAYS360(M9,TODAY()) -> 474 | M9: 45326 | O9: =EDATE(M9,6) -> 45508 | P9: =DAYS360(O9,TODAY()) -> 294
B10: Cielo Rosso | C10: Naveen | D10: =DAYS360(E10,TODAY()) -> 174 | E10: 45630 | G10: =EDATE(E10,12) -> 45995 | H10: =DAYS360(I10,TODAY()) -> 174 | I10: 45630 | K10: =EDATE(I10,12) -> 45995 | L10: =DAYS360(M10,TODAY()) -> 562 | M10: 45236 | O10: =EDATE(M10,6) -> 45418 | P10: =DAYS360(O10,TODAY()) -> 382
B11: Clearocean Maria | C11: Avish | D11: =DAYS360(E11,TODAY()) -> 248 | E11: 45555 | G11: =EDATE(E11,12) -> 45920 | H11: =DAYS360(I11,TODAY()) -> 248 | I11: 45555 | K11: =EDATE(I11,12) -> 45920 | L11: =DAYS360(M11,TODAY()) -> 382 | M11: 45418 | O11: =EDATE(M11,6) -> 45602 | P11: =DAYS360(O11,TODAY()) -> 202
B12: Clearocean Mary | C12: Rajneesh | D12: =DAYS360(E12,TODAY()) -> 182 | E12: 45622 | G12: =EDATE(E12,12) -> 45987 | H12: =DAYS360(I12,TODAY()) -> 182 | I12: 45622 | K12: =EDATE(I12,12) -> 45987 | L12: =DAYS360(M12,TODAY()) -> 375 | M12: 45425 | O12: =EDATE(M12,6) -> 45609 | P12: =DAYS360(O12,TODAY()) -> 195
B13: Clearocean Mathilde | C13: Jay | D13: =DAYS360(E13,TODAY()) -> 298 | E13: 45504 | G13: =EDATE(E13,12) -> 45869 | H13: =DAYS360(I13,TODAY()) -> 298 | I13: 45504 | K13: =EDATE(I13,12) -> 45869 | L13: =DAYS360(M13,TODAY()) -> 423 | M13: 45376 | O13: =EDATE(M13,6) -> 45560 | P13: =DAYS360(O13,TODAY()) -> 243
B14: Clearocean Music | C14: Jay | D14: =DAYS360(E14,TODAY()) -> 272 | E14: 45530 | G14: =EDATE(E14,12) -> 45895 | H14: =DAYS360(I14,TODAY()) -> 213 | I14: 45590 | K14: =EDATE(I14,12) -> 45955 | L14: =DAYS360(M14,TODAY()) -> 417 | M14: 45383 | O14: =EDATE(M14,6) -> 45566 | P14: =DAYS360(O14,TODAY()) -> 237
B15: Rui Fu Xing (Glenda Melanie) | C15: Siddharth | D15: =DAYS360(E15,TODAY()) -> 362 | E15: 45438 | G15: =EDATE(E15,12) -> 45803 | H15: =DAYS360(I15,TODAY()) -> 362 | I15: 45438 | K15: =EDATE(I15,12) -> 45803 | L15: =DAYS360(M15,TODAY()) -> 472 | M15: 45328 | O15: =EDATE(M15,6) -> 45510 | P15: =DAYS360(O15,TODAY()) -> 292
B16: Glenda Melissa | C16: Ashwin | D16: =DAYS360(E16,TODAY()) -> 472 | E16: 45328 | G16: =EDATE(E16,12) -> 45694 | H16: =DAYS360(I16,TODAY()) -> 472 | I16: 45328 | K16: =EDATE(I16,12) -> 45694 | L16: =DAYS360(M16,TODAY()) -> 284 | M16: 45518 | O16: =EDATE(M16,6) -> 45702 | P16: =DAYS360(O16,TODAY()) -> 104
B17: Glenda Melody | C17: Siddharth | D17: =DAYS360(E17,TODAY()) -> 400 | E17: 45400 | G17: =EDATE(E17,12) -> 45765 | H17: =DAYS360(I17,TODAY()) -> 667 | I17: 45128 | K17: =EDATE(I17,12) -> 45494 | L17: =DAYS360(M17,TODAY()) -> 404 | M17: 45396 | O17: =EDATE(M17,6) -> 45579 | P17: =DAYS360(O17,TODAY()) -> 224
B18: Glenda Meryl | C18: Kaustubh | D18: =DAYS360(E18,TODAY()) -> 215 | E18: 45588 | G18: =EDATE(E18,12) -> 45953 | H18: =DAYS360(I18,TODAY()) -> 215 | I18: 45588 | K18: =EDATE(I18,12) -> 45953 | L18: =DAYS360(M18,TODAY()) -> 365 | M18: 45435 | O18: =EDATE(M18,6) -> 45619 | P18: =DAYS360(O18,TODAY()) -> 185
B19: Herolds Bay | C19: Kaustubh | D19: =DAYS360(E19,TODAY()) -> 232 | E19: 45571 | G19: =EDATE(E19,12) -> 45936 | H19: =DAYS360(I19,TODAY()) -> 232 | I19: 45571 | K19: =EDATE(I19,12) -> 45936 | L19: =DAYS360(M19,TODAY()) -> 312 | M19: 45489 | O19: =EDATE(M19,6) -> 45673 | P19: =DAYS360(O19,TODAY()) -> 132
B20: High Explorer | C20: Lalit | D20: =DAYS360(E20,TODAY()) -> 271 | E20: 45531 | G20: =EDATE(E20,12) -> 45896 | H20: =DAYS360(I20,TODAY()) -> 271 | I20: 45531 | K20: =EDATE(I20,12) -> 45896 | L20: =DAYS360(M20,TODAY()) -> 480 | M20: 45319 | O20: =EDATE(M20,6) -> 45501 | P20: =DAYS360(O20,TODAY()) -> 300
B21: High Mariner | D21: =DAYS360(E21,TODAY()) -> 45148 | H21: =DAYS360(I21,TODAY()) -> 45148 | L21: =DAYS360(M21,TODAY()) -> 45148 | P21: =DAYS360(O21,TODAY()) -> 45148
B22: High Transporter | C22: Rajneesh | D22: =DAYS360(E22,TODAY()) -> 226 | E22: 45577 | G22: =EDATE(E22,12) -> 45942 | H22: =DAYS360(I22,TODAY()) -> 226 | I22: 45577 | K22: =EDATE(I22,12) -> 45942 | L22: =DAYS360(M22,TODAY()) -> 295 | M22: 45507 | O22: =EDATE(M22,6) -> 45691 | P22: =DAYS360(O22,TODAY()) -> 115
B23: Kalk Bay | C23: Venster | D23: =DAYS360(E23,TODAY()) -> 390 | E23: 45410 | G23: =EDATE(E23,12) -> 45775 | H23: =DAYS360(I23,TODAY()) -> 390 | I23: 45410 | K23: =EDATE(I23,12) -> 45775 | L23: =DAYS360(M23,TODAY()) -> 530 | M23: 45268 | O23: =EDATE(M23,6) -> 45451 | P23: =DAYS360(O23,TODAY()) -> 350
B24: Mossel Bay | C24: Siddharth | D24: =DAYS360(E24,TODAY()) -> 169 | E24: 45635 | G24: =EDATE(E24,12) -> 46000 | H24: =DAYS360(I24,TODAY()) -> 169 | I24: 45635 | K24: =EDATE(I24,12) -> 46000 | L24: =DAYS360(M24,TODAY()) -> 264 | M24: 45539 | O24: =EDATE(M24,6) -> 45720 | P24: =DAYS360(O24,TODAY()) -> 84
B25: Philotimos | C25: Jay | D25: =DAYS360(E25,TODAY()) -> 291 | E25: 45511 | G25: =EDATE(E25,12) -> 45876 | H25: =DAYS360(I25,TODAY()) -> 291 | I25: 45511 | K25: =EDATE(I25,12) -> 45876 | P25: =DAYS360(O25,TODAY()) -> 45148
B26: Philoxenia | C26: Jay | D26: =DAYS360(E26,TODAY()) -> 183 | E26: 45621 | G26: =EDATE(E26,12) -> 45986 | H26: =DAYS360(I26,TODAY()) -> 159 | I26: 45645 | K26: =EDATE(I26,12) -> 46010 | L26: =DAYS360(M26,TODAY()) -> 365 | M26: 45435 | O26: =EDATE(M26,6) -> 45619 | P26: =DAYS360(O26,TODAY()) -> 185
B27: PNX Conqueror | C27: Jay | D27: =DAYS360(E27,TODAY()) -> 495 | E27: 45304 | G27: =EDATE(E27,12) -> 45670 | H27: =DAYS360(I27,TODAY()) -> 495 | I27: 45304 | K27: =EDATE(I27,12) -> 45670 | L27: =DAYS360(M27,TODAY()) -> 618 | M27: 45179 | O27: =EDATE(M27,6) -> 45361 | P27: =DAYS360(O27,TODAY()) -> 438
B28: PS Tokyo (Gone) | C28: Venster | D28: =DAYS360(E28,TODAY()) -> 544 | E28: 45254 | G28: =EDATE(E28,12) -> 45620 | H28: =DAYS360(I28,TODAY()) -> 472 | I28: 45328 | K28: =EDATE(I28,12) -> 45694 | L28: =DAYS360(M28,TODAY()) -> 993 | M28: 44798 | O28: =EDATE(M28,6) -> 44982 | P28: =DAYS360(O28,TODAY()) -> 813
B29: PS Vancouver | C29: Jay | D29: =DAYS360(E29,TODAY()) -> 240 | E29: 45563 | G29: =EDATE(E29,12) -> 45928 | H29: =DAYS360(I29,TODAY()) -> 240 | I29: 45563 | K29: =EDATE(I29,12) -> 45928 | L29: =DAYS360(M29,TODAY()) -> 242 | M29: 45561 | O29: =EDATE(M29,6) -> 45742 | P29: =DAYS360(O29,TODAY()) -> 62
B30: Table Bay | C30: Jay | D30: =DAYS360(E30,TODAY()) -> 336 | E30: 45465 | G30: =EDATE(E30,12) -> 45830 | H30: =DAYS360(I30,TODAY()) -> 336 | I30: 45465 | K30: =EDATE(I30,12) -> 45830 | L30: =DAYS360(M30,TODAY()) -> 447 | M30: 45352 | O30: =EDATE(M30,6) -> 45536 | P30: =DAYS360(O30,TODAY()) -> 267
B31: Rui Fu Sheng | C31: Jay | D31: =DAYS360(E31,TODAY()) -> 347 | E31: 45454 | G31: =EDATE(E31,12) -> 45819 | H31: =DAYS360(I31,TODAY()) -> 45148 | K31: =EDATE(I31,12) -> 366 | L31: =DAYS360(M31,TODAY()) -> 305 | M31: 45496 | O31: =EDATE(M31,6) -> 45680 | P31: =DAYS360(O31,TODAY()) -> 125
B32: Vialli | C32: Rajneesh | D32: =DAYS360(E32,TODAY()) -> 492 | E32: 45307 | G32: =EDATE(E32,12) -> 45673 | H32: =DAYS360(I32,TODAY()) -> 492 | I32: 45307 | K32: =EDATE(I32,12) -> 45673 | L32: =DAYS360(M32,TODAY()) -> 518 | M32: 45280 | O32: =EDATE(M32,6) -> 45463 | P32: =DAYS360(O32,TODAY()) -> 338
B33: Victoria Bay | C33: Jay | D33: =DAYS360(E33,TODAY()) -> 333 | E33: 45468 | G33: =EDATE(E33,12) -> 45833 | H33: =DAYS360(I33,TODAY()) -> 333 | I33: 45468 | K33: =EDATE(I33,12) -> 45833 | L33: =DAYS360(M33,TODAY()) -> 45148 | P33: =DAYS360(O33,TODAY()) -> 45148

Sheet Dry Data
D1: INTERNAL AUDIT 2024 | I1: SAFETY INSPECTION 2024 | N1: NAVIGATIONAL AUDIT 2024 | S1: ENVIRONMENTAL AUDIT 2024 | X1: CARGO OPERATION AUDIT 2024 | AC1: ISPS AUDIT 2024 | AH1: MOORING AUDIT 2024
A2: Vessel | B2: Auditor Name | C2: Place | D2: Internal Audit date | E2: Report date | F2: Remarks | G2: NC | H2: Obs | I2: Safety Inspection date | J2: Report date | K2: Remarks | L2: Nc | M2: Obs | N2: Nav Audit date | O2: Report date | P2: Remarks | Q2: NC | R2: Obs | S2: Env Audit date | T2: Report date | U2: Remarks | V2: Nc | W2: Obs | X2: Cargo Op Audit date | Y2: Report date | Z2: Remarks | AA2: Nc | AB2: Obs | AC2: ISPS Audit date | AD2: Report date | AE2: Remarks | AF2: Nc | AG2: Obs | AH2: Imooriong Audit date | AI2: Report date | AJ2: Remarks | AK2: Nc | AL2: Obs | AM2: Training Date | AN2: Vetting Date Company | AP2: Embarkation Port | AQ2: Disembarkation Port | AR2: Travel out | AS2: Onboard | AT2: Off vessel | AU2: Travel in | AV2: Total days | AW2: Total days on Board
A3: =' IA-SI DRY'!B4 -> Cielo di Valparaiso | F3: =G3+H3 -> 0 | K3: =L3+M3 -> 0 | P3: =Q3+R3 -> 0 | U3: =V3+W3 -> 0 | AE3: =AF3+AG3 -> 0 | AJ3: =AK3+AL3 -> 0 | AV3: =AU3-AR3 -> 0 | AW3: =AT3-AS3 -> 0
F4: =G4+H4 -> 0 | K4: =L4+M4 -> 0 | P4: =Q4+R4 -> 0 | U4: =V4+W4 -> 0 | AE4: =AF4+AG4 -> 0 | AJ4: =AK4+AL4 -> 0 | AV4: =AU4-AR4 -> 0 | AW4: =AT4-AS4 -> 0
F5: =G5+H5 -> 0 | K5: =L5+M5 -> 0 | P5: =Q5+R5 -> 0 | U5: =V5+W5 -> 0 | AE5: =AF5+AG5 -> 0 | AJ5: =AK5+AL5 -> 0 | AV5: =AU5-AR5 -> 0 | AW5: =AT5-AS5 -> 0
F6: =G6+H6 -> 0 | K6: =L6+M6 -> 0 | P6: =Q6+R6 -> 0 | U6: =V6+W6 -> 0 | AE6: =AF6+AG6 -> 0 | AJ6: =AK6+AL6 -> 0 | AV6: =AU6-AR6 -> 0 | AW6: =AT6-AS6 -> 0
A7: =' IA-SI DRY'!B5 -> Cielo Dei Maronti | B7: Rajneesh | C7: Port/Navigation | D7: 07.08.2024 | E7: 07.08.2024 | F7: =G7+H7 -> 4 | G7: 0 | H7: 4 | K7: =L7+M7 -> 0 | N7: 07.08.2024 | O7: 07.08.2024 | P7: =Q7+R7 -> 5 | Q7: 0 | R7: 5 | U7: =V7+W7 -> 0 | AC7: 07.08.2024 | AD7: 07.08.2024 | AE7: =AF7+AG7 -> 0 | AF7: 0 | AG7: 0 | AJ7: =AK7+AL7 -> 0 | AP7: Cristobal | AQ7: Balboa | AR7: 45508 | AS7: 45509 | AT7: 45511 | AU7: 45514 | AV7: =AU7-AR7 -> 6 | AW7: =AT7-AS7 -> 2
F8: =G8+H8 -> 0 | K8: =L8+M8 -> 0 | P8: =Q8+R8 -> 0 | U8: =V8+W8 -> 0 | AE8: =AF8+AG8 -> 0 | AJ8: =AK8+AL8 -> 0 | AV8: =AU8-AR8 -> 0 | AW8: =AT8-AS8 -> 0
F9: =G9+H9 -> 0 | K9: =L9+M9 -> 0 | P9: =Q9+R9 -> 0 | U9: =V9+W9 -> 0 | AE9: =AF9+AG9 -> 0 | AJ9: =AK9+AL9 -> 0 | AV9: =AU9-AR9 -> 0 | AW9: =AT9-AS9 -> 0
F10: =G10+H10 -> 0 | K10: =L10+M10 -> 0 | P10: =Q10+R10 -> 0 | U10: =V10+W10 -> 0 | AE10: =AF10+AG10 -> 0 | AJ10: =AK10+AL10 -> 0 | AV10: =AU10-AR10 -> 0 | AW10: =AT10-AS10 -> 0
A11: =' IA-SI DRY'!B6 -> Medi Adriatico | B11: Others | C11: Port/Navigation | D11: 02-08-2024 | E11: 22-08-24 | F11: =G11+H11 -> 3 | G11: 0 | H11: 3 | I11: 02.08.2024 | J11: 22.08.2024 | K11: =L11+M11 -> 5 | L11: 0 | M11: 5 | P11: =Q11+R11 -> 0 | U11: =V11+W11 -> 0 | AC11: 02.08.2024 | AD11: 22.08.2024 | AE11: =AF11+AG11 -> 0 | AF11: 0 | AG11: 0 | AJ11: =AK11+AL11 -> 0 | AP11: Mobile | AQ11: Mobile | AR11: 45506 | AS11: 45506 | AT11: 45509 | AU11: 45509 | AV11: =AU11-AR11 -> 3 | AW11: =AT11-AS11 -> 3
F12: =G12+H12 -> 0 | K12: =L12+M12 -> 0 | P12: =Q12+R12 -> 0 | U12: =V12+W12 -> 0 | AE12: =AF12+AG12 -> 0 | AJ12: =AK12+AL12 -> 0 | AV12: =AU12-AR12 -> 0 | AW12: =AT12-AS12 -> 0
F13: =G13+H13 -> 0 | K13: =L13+M13 -> 0 | P13: =Q13+R13 -> 0 | U13: =V13+W13 -> 0 | AE13: =AF13+AG13 -> 0 | AJ13: =AK13+AL13 -> 0 | AV13: =AU13-AR13 -> 0 | AW13: =AT13-AS13 -> 0
F14: =G14+H14 -> 0 | K14: =L14+M14 -> 0 | P14: =Q14+R14 -> 0 | U14: =V14+W14 -> 0 | AE14: =AF14+AG14 -> 0 | AJ14: =AK14+AL14 -> 0 | AV14: =AU14-AR14 -> 0 | AW14: =AT14-AS14 -> 0
A15: =' IA-SI DRY'!B7 -> Medi Atlantico | B15: Naveen | C15: Port | D15: 26.06.2024 | E15: 26.06.2024 | F15: =G15+H15 -> 5 | G15: 0 | H15: 5 | K15: =L15+M15 -> 0 | P15: =Q15+R15 -> 0 | U15: =V15+W15 -> 0 | AC15: 26.06.2024 | AD15: 26.06.2024 | AE15: =AF15+AG15 -> 0 | AF15: 0 | AG15: 0 | AJ15: =AK15+AL15 -> 0 | AP15: Zhangjiagang | AQ15: Zhangjiagang | AR15: 45466 | AS15: 45467 | AT15: 45469 | AU15: 45471 | AV15: =AU15-AR15 -> 5 | AW15: =AT15-AS15 -> 2
F16: =G16+H16 -> 0 | K16: =L16+M16 -> 0 | P16: =Q16+R16 -> 0 | U16: =V16+W16 -> 0 | AE16: =AF16+AG16 -> 0 | AJ16: =AK16+AL16 -> 0 | AV16: =AU16-AR16 -> 0 | AW16: =AT16-AS16 -> 0
F17: =G17+H17 -> 0 | K17: =L17+M17 -> 0 | P17: =Q17+R17 -> 0 | U17: =V17+W17 -> 0 | AE17: =AF17+AG17 -> 0 | AJ17: =AK17+AL17 -> 0 | AV17: =AU17-AR17 -> 0 | AW17: =AT17-AS17 -> 0
F18: =G18+H18 -> 0 | K18: =L18+M18 -> 0 | P18: =Q18+R18 -> 0 | U18: =V18+W18 -> 0 | AE18: =AF18+AG18 -> 0 | AJ18: =AK18+AL18 -> 0 | AV18: =AU18-AR18 -> 0 | AW18: =AT18-AS18 -> 0
A19: Medi Caboto | F19: =G19+H19 -> 0 | K19: =L19+M19 -> 0 | P19: =Q19+R19 -> 0 | U19: =V19+W19 -> 0 | AE19: =AF19+AG19 -> 0 | AJ19: =AK19+AL19 -> 0 | AV19: =AU19-AR19 -> 0 | AW19: =AT19-AS19 -> 0
F20: =G20+H20 -> 0 | K20: =L20+M20 -> 0 | P20: =Q20+R20 -> 0 | U20: =V20+W20 -> 0 | AE20: =AF20+AG20 -> 0 | AJ20: =AK20+AL20 -> 0 | AV20: =AU20-AR20 -> 0 | AW20: =AT20-AS20 -> 0
F21: =G21+H21 -> 0 | K21: =L21+M21 -> 0 | P21: =Q21+R21 -> 0 | U21: =V21+W21 -> 0 | AE21: =AF21+AG21 -> 0 | AJ21: =AK21+AL21 -> 0 | AV21: =AU21-AR21 -> 0 | AW21: =AT21-AS21 -> 0
F22: =G22+H22 -> 0 | K22: =L22+M22 -> 0 | P22: =Q22+R22 -> 0 | U22: =V22+W22 -> 0 | AE22: =AF22+AG22 -> 0 | AJ22: =AK22+AL22 -> 0 | AV22: =AU22-AR22 -> 0 | AW22: =AT22-AS22 -> 0
A23: =' IA-SI DRY'!B8 -> Medi Egadi | B23: Avish | C23: Port | D23: 08.08.2024 | E23: 08.08.2024 | F23: =G23+H23 -> 3 | G23: 0 | H23: 3 | K23: =L23+M23 -> 0 | P23: =Q23+R23 -> 0 | S23: 08.08.2024 | T23: 08.08.2024 | U23: =V23+W23 -> 1 | V23: 0 | W23: 1 | AC23: 08.08.2024 | AD23: 08.08.2024 | AE23: =AF23+AG23 -> 0 | AF23: 0 | AG23: 0 | AJ23: =AK23+AL23 -> 0 | AP23: Singapore | AQ23: Singapore | AR23: 45512 | AS23: 45512 | AT23: 45512 | AU23: 45512 | AV23: =AU23-AR23 -> 0 | AW23: =AT23-AS23 -> 0
F24: =G24+H24 -> 0 | K24: =L24+M24 -> 0 | P24: =Q24+R24 -> 0 | U24: =V24+W24 -> 0 | AE24: =AF24+AG24 -> 0 | AJ24: =AK24+AL24 -> 0 | AV24: =AU24-AR24 -> 0 | AW24: =AT24-AS24 -> 0
F25: =G25+H25 -> 0 | K25: =L25+M25 -> 0 | P25: =Q25+R25 -> 0 | U25: =V25+W25 -> 0 | AE25: =AF25+AG25 -> 0 | AJ25: =AK25+AL25 -> 0 | AV25: =AU25-AR25 -> 0 | AW25: =AT25-AS25 -> 0
F26: =G26+H26 -> 0 | K26: =L26+M26 -> 0 | P26: =Q26+R26 -> 0 | U26: =V26+W26 -> 0 | AE26: =AF26+AG26 -> 0 | AJ26: =AK26+AL26 -> 0 | AV26: =AU26-AR26 -> 0 | AW26: =AT26-AS26 -> 0
A27: =' IA-SI DRY'!B9 -> Medi Egeo | B27: Naveen | C27: Port | D27: 30.09.2024 | E27: 30.09.2024 | F27: =G27+H27 -> 3 | G27: 0 | H27: 3 | K27: =L27+M27 -> 0 | P27: =Q27+R27 -> 0 | U27: =V27+W27 -> 0 | AC27: 30.09.2024 | AD27: 30.09.2024 | AE27: =AF27+AG27 -> 0 | AF27: 0 | AG27: 0 | AJ27: =AK27+AL27 -> 0 | AP27: Kaohsiung | AQ27: Kaohsiung | AR27: 45563 | AS27: 45564 | AT27: 45565 | AU27: 45566 | AV27: =AU27-AR27 -> 3 | AW27: =AT27-AS27 -> 1
F28: =G28+H28 -> 0 | K28: =L28+M28 -> 0 | P28: =Q28+R28 -> 0 | U28: =V28+W28 -> 0 | AE28: =AF28+AG28 -> 0 | AJ28: =AK28+AL28 -> 0 | AV28: =AU28-AR28 -> 0 | AW28: =AT28-AS28 -> 0
F29: =G29+H29 -> 0 | K29: =L29+M29 -> 0 | P29: =Q29+R29 -> 0 | U29: =V29+W29 -> 0 | AE29: =AF29+AG29 -> 0 | AJ29: =AK29+AL29 -> 0 | AV29: =AU29-AR29 -> 0 | AW29: =AT29-AS29 -> 0
F30: =G30+H30 -> 0 | K30: =L30+M30 -> 0 | P30: =Q30+R30 -> 0 | U30: =V30+W30 -> 0 | AE30: =AF30+AG30 -> 0 | AJ30: =AK30+AL30 -> 0 | AV30: =AU30-AR30 -> 0 | AW30: =AT30-AS30 -> 0
A31: =' IA-SI DRY'!B10 -> Medi Matsuura | B31: Naveen | C31: Port | D31: 30.10.2024 | E31: 30.10.2024 | F31: =G31+H31 -> 4 | G31: 0 | H31: 4 | I31: 30.10.2024 | J31: 30.10.2024 | K31: =L31+M31 -> 2 | L31: 0 | M31: 2 | P31: =Q31+R31 -> 0 | U31: =V31+W31 -> 0 | AC31: 30.10.2024 | AD31: 30.10.2024 | AE31: =AF31+AG31 -> 0 | AF31: 0 | AG31: 0 | AJ31: =AK31+AL31 -> 0 | AP31: Onahama | AQ31: Onahama | AR31: 45589 | AS31: 45591 | AT31: 45596 | AU31: 45596 | AV31: =AU31-AR31 -> 7 | AW31: =AT31-AS31 -> 5
F32: =G32+H32 -> 0 | K32: =L32+M32 -> 0 | P32: =Q32+R32 -> 0 | U32: =V32+W32 -> 0 | AE32: =AF32+AG32 -> 0 | AJ32: =AK32+AL32 -> 0 | AV32: =AU32-AR32 -> 0 | AW32: =AT32-AS32 -> 0
F33: =G33+H33 -> 0 | K33: =L33+M33 -> 0 | P33: =Q33+R33 -> 0 | U33: =V33+W33 -> 0 | AE33: =AF33+AG33 -> 0 | AJ33: =AK33+AL33 -> 0 | AV33: =AU33-AR33 -> 0 | AW33: =AT33-AS33 -> 0
F34: =G34+H34 -> 0 | K34: =L34+M34 -> 0 | P34: =Q34+R34 -> 0 | U34: =V34+W34 -> 0 | AE34: =AF34+AG34 -> 0 | AJ34: =AK34+AL34 -> 0 | AV34: =AU34-AR34 -> 0 | AW34: =AT34-AS34 -> 0
A35: =' IA-SI DRY'!B11 -> Medi Palmarola | B35: Lalit | C35: Port/Navigation | D35: 28.07.2024 | E35: 28.07.2024 | F35: =G35+H35 -> 5 | G35: 2 | H35: 3 | I35: 28.07.2024 | J35: 28.07.2024 | K35: =L35+M35 -> 6 | L35: 1 | M35: 5 | N35: 28.07.2024 | O35: 28.07.2024 | P35: =Q35+R35 -> 5 | Q35: 3 | R35: 2 | S35: 28.07.2024 | T35: 28.07.2024 | U35: =V35+W35 -> 4 | V35: 1 | W35: 3 | AC35: 28.07.2024 | AD35: 28.07.2024 | AE35: =AF35+AG35 -> 0 | AF35: 0 | AG35: 0 | AH35: 28.07.2027 | AI35: 28.07.2024 | AJ35: =AK35+AL35 -> 6 | AK35: 2 | AL35: 4 | AP35: Paradip | AQ35: Haldia | AR35: 45495 | AS35: 45497 | AT35: 45501 | AU35: 45501 | AV35: =AU35-AR35 -> 6 | AW35: =AT35-AS35 -> 4
F36: =G36+H36 -> 0 | K36: =L36+M36 -> 0 | P36: =Q36+R36 -> 0 | U36: =V36+W36 -> 0 | AE36: =AF36+AG36 -> 0 | AJ36: =AK36+AL36 -> 0 | AV36: =AU36-AR36 -> 0 | AW36: =AT36-AS36 -> 0
F37: =G37+H37 -> 0 | K37: =L37+M37 -> 0 | P37: =Q37+R37 -> 0 | U37: =V37+W37 -> 0 | AE37: =AF37+AG37 -> 0 | AJ37: =AK37+AL37 -> 0 | AV37: =AU37-AR37 -> 0 | AW37: =AT37-AS37 -> 0
F38: =G38+H38 -> 0 | K38: =L38+M38 -> 0 | P38: =Q38+R38 -> 0 | U38: =V38+W38 -> 0 | AE38: =AF38+AG38 -> 0 | AJ38: =AK38+AL38 -> 0 | AV38: =AU38-AR38 -> 0 | AW38: =AT38-AS38 -> 0
A39: =' IA-SI DRY'!B12 -> Medi Sydney | B39: Siddharth | C39: Port | D39: 06.10.2024 | E39: 06.10.2024 | F39: =G39+H39 -> 6 | G39: 1 | H39: 5 | I39: 06.10.2024 | J39: 06.10.2024 | K39: =L39+M39 -> 7 | L39: 0 | M39: 7 | P39: =Q39+R39 -> 0 | U39: =V39+W39 -> 0 | AC39: 06.10.2024 | AD39: 06.10.2024 | AE39: 0 | AF39: 0 | AG39: 0 | AP39: Haldia | AQ39: Haldia | AR39: 45569 | AS39: 45570 | AT39: 45571 | AU39: 45572 | AV39: =AU39-AR39 -> 3 | AW39: =AT39-AS39 -> 1
F40: =G40+H40 -> 0 | K40: =L40+M40 -> 0 | P40: =Q40+R40 -> 0 | U40: =V40+W40 -> 0 | AE40: =AF40+AG40 -> 0 | AV40: =AU40-AR40 -> 0 | AW40: =AT40-AS40 -> 0
...

Sheet Tanker Data
D1: INTERNAL AUDIT 2024 | I1: SAFETY INSPECTION 2024 | N1: NAVIGATIONAL AUDIT 2024 | S1: ENVIRONMENTAL AUDIT 2024 | X1: CARGO OPERATION AUDIT 2024 | AC1: ISPS AUDIT 2024 | AH1: MOORING AUDIT 2024 | AR1: Date: dd/mm/yyyy
A2: Vessel | B2: Auditor Name | C2: Place | D2: Internal Audit date | E2: Report date | F2: Remarks | G2: NC | H2: Obs | I2: Safety Inspection date | J2: Report date | K2: Remarks | L2: NC | M2: Obs | N2: Nav Audit date | O2: Report date | P2: Remarks | Q2: NC | R2: Obs | S2: Env Audit date | T2: Report date | U2: Remarks | V2: NC | W2: Obs | X2: Cargo Op Audit date | Y2: Report date | Z2: Remarks | AA2: NC | AB2: Obs | AC2: ISPS Audit date | AD2: Report date | AE2: Remarks | AF2: NC | AG2: Obs | AH2: Mooring Audit date | AI2: Report date | AJ2: Remarks | AK2: NC | AL2: Obs | AM2: Training Date | AN2: Vetting Date Company | AP2: Embarkation Port | AQ2: Disembarkation Port | AR2: Travel out | AS2: Onboard | AT2: Off vessel | AU2: Travel in | AV2: Total days | AW2: Days on board
A3: ='IA-SI TANKER'!B4 -> Alpine Pembroke (Sold) | F3: =G3+H3 -> 0 | K3: =L3+M3 -> 0 | P3: =Q3+R3 -> 0 | U3: =V3+W3 -> 0 | Z3: =AA3+AB3 -> 0 | AE3: =AF3+AG3 -> 0 | AJ3: =AK3+AL3 -> 0 | AV3: =AU3-AR3 -> 0 | AW3: =AT3-AS3 -> 0
F4: =G4+H4 -> 0 | K4: =L4+M4 -> 0 | P4: =Q4+R4 -> 0 | U4: =V4+W4 -> 0 | Z4: =AA4+AB4 -> 0 | AE4: =AF4+AG4 -> 0 | AJ4: =AK4+AL4 -> 0 | AV4: =AU4-AR4 -> 0 | AW4: =AT4-AS4 -> 0
F5: =G5+H5 -> 0 | K5: =L5+M5 -> 0 | P5: =Q5+R5 -> 0 | U5: =V5+W5 -> 0 | Z5: =AA5+AB5 -> 0 | AE5: =AF5+AG5 -> 0 | AJ5: =AK5+AL5 -> 0 | AV5: =AU5-AR5 -> 0 | AW5: =AT5-AS5 -> 0
F6: =G6+H6 -> 0 | K6: =L6+M6 -> 0 | P6: =Q6+R6 -> 0 | U6: =V6+W6 -> 0 | Z6: =AA6+AB6 -> 0 | AE6: =AF6+AG6 -> 0 | AJ6: =AK6+AL6 -> 0 | AV6: =AU6-AR6 -> 0 | AW6: =AT6-AS6 -> 0
A7: ='IA-SI TANKER'!B5 -> Alpine Pioneer (Sold) | F7: =G7+H7 -> 0 | K7: =L7+M7 -> 0 | P7: =Q7+R7 -> 0 | U7: =V7+W7 -> 0 | Z7: =AA7+AB7 -> 0 | AE7: =AF7+AG7 -> 0 | AJ7: =AK7+AL7 -> 0 | AV7: =AU7-AR7 -> 0 | AW7: =AT7-AS7 -> 0
F8: =G8+H8 -> 0 | K8: =L8+M8 -> 0 | P8: =Q8+R8 -> 0 | U8: =V8+W8 -> 0 | Z8: =AA8+AB8 -> 0 | AE8: =AF8+AG8 -> 0 | AJ8: =AK8+AL8 -> 0 | AV8: =AU8-AR8 -> 0 | AW8: =AT8-AS8 -> 0
F9: =G9+H9 -> 0 | K9: =L9+M9 -> 0 | P9: =Q9+R9 -> 0 | U9: =V9+W9 -> 0 | Z9: =AA9+AB9 -> 0 | AE9: =AF9+AG9 -> 0 | AJ9: =AK9+AL9 -> 0 | AV9: =AU9-AR9 -> 0 | AW9: =AT9-AS9 -> 0
F10: =G10+H10 -> 0 | K10: =L10+M10 -> 0 | P10: =Q10+R10 -> 0 | U10: =V10+W10 -> 0 | Z10: =AA10+AB10 -> 0 | AE10: =AF10+AG10 -> 0 | AJ10: =AK10+AL10 -> 0 | AV10: =AU10-AR10 -> 0 | AW10: =AT10-AS10 -> 0
A11: ='IA-SI TANKER'!B6 -> Bagheera | B11: Naveen | C11: Port/Navigation | D11: 01.05.2024 | E11: 01.05.2024 | F11: =G11+H11 -> 5 | G11: 0 | H11: 5 | I11: 01.05.2024 | J11: 01.05.2024 | K11: =L11+M11 -> 5 | L11: 0 | M11: 5 | N11: 01.05.2024 | O11: 45413 | P11: =Q11+R11 -> 3 | Q11: 0 | R11: 3 | S11: 01.05.2024 | T11: 01.05.2024 | U11: =V11+W11 -> 2 | V11: 0 | W11: 2 | X11: 01.05.2024 | Y11: 01.05.2024 | Z11: =AA11+AB11 -> 4 | AA11: 0 | AB11: 4 | AC11: 01.05.2024 | AD11: 01.05.2024 | AE11: =AF11+AG11 -> 0 | AF11: 0 | AG11: 0 | AH11: 01.05.2024 | AI11: 01.05.2024 | AJ11: =AK11+AL11 -> 2 | AK11: 0 | AL11: 2 | AM11: 01.05.2024 | AP11: Fos | AQ11: Lavera | AR11: 45399 | AS11: 45399 | AT11: 45413 | AU11: 45415 | AV11: =AU11-AR11 -> 16 | AW11: =AT11-AS11 -> 14
F12: =G12+H12 -> 0 | K12: =L12+M12 -> 0 | P12: =Q12+R12 -> 0 | U12: =V12+W12 -> 0 | Z12: =AA12+AB12 -> 0 | AE12: =AF12+AG12 -> 0 | AJ12: =AK12+AL12 -> 0 | AV12: =AU12-AR12 -> 0 | AW12: =AT12-AS12 -> 0
F13: =G13+H13 -> 0 | K13: =L13+M13 -> 0 | P13: =Q13+R13 -> 0 | U13: =V13+W13 -> 0 | Z13: =AA13+AB13 -> 0 | AE13: =AF13+AG13 -> 0 | AJ13: =AK13+AL13 -> 0 | AV13: =AU13-AR13 -> 0 | AW13: =AT13-AS13 -> 0
F14: =G14+H14 -> 0 | K14: =L14+M14 -> 0 | P14: =Q14+R14 -> 0 | U14: =V14+W14 -> 0 | Z14: =AA14+AB14 -> 0 | AE14: =AF14+AG14 -> 0 | AJ14: =AK14+AL14 -> 0 | AV14: =AU14-AR14 -> 0 | AW14: =AT14-AS14 -> 0
A15: Bantry Bay | B15: Rajneesh | C15: Port/Navigation | D15: 22.08.2024 | E15: 22.08.2024 | F15: =G15+H15 -> 6 | G15: 0 | H15: 6 | I15: 22.08.2024 | J15: 22.08.2024 | K15: =L15+M15 -> 6 | L15: 0 | M15: 6 | N15: 22.08.2024 | O15: 22.08.2024 | P15: =Q15+R15 -> 3 | Q15: 0 | R15: 3 | S15: 22.08.2024 | T15: 22.08.2024 | U15: =V15+W15 -> 6 | V15: 0 | W15: 6 | X15: 22.08.2024 | Y15: 22.08.2024 | Z15: =AA15+AB15 -> 6 | AA15: 0 | AB15: 6 | AC15: 22.08.2024 | AD15: 22.08.2024 | AE15: =AF15+AG15 -> 0 | AF15: 0 | AG15: 0 | AH15: 22.08.2024 | AI15: 22.08.2024 | AJ15: =AK15+AL15 -> 3 | AK15: 0 | AL15: 3 | AM15: 22.08.2024 | AP15: St Charles | AQ15: Balboa | AR15: 45515 | AS15: 45517 | AT15: 45526 | AU15: 45529 | AV15: =AU15-AR15 -> 14 | AW15: =AT15-AS15 -> 9
F16: =G16+H16 -> 0 | K16: =L16+M16 -> 0 | P16: =Q16+R16 -> 0 | U16: =V16+W16 -> 0 | Z16: =AA16+AB16 -> 0 | AE16: =AF16+AG16 -> 0 | AJ16: =AK16+AL16 -> 0 | AV16: =AU16-AR16 -> 0 | AW16: =AT16-AS16 -> 0
F17: =G17+H17 -> 0 | K17: =L17+M17 -> 0 | P17: =Q17+R17 -> 0 | U17: =V17+W17 -> 0 | Z17: =AA17+AB17 -> 0 | AE17: =AF17+AG17 -> 0 | AJ17: =AK17+AL17 -> 0 | AV17: =AU17-AR17 -> 0 | AW17: =AT17-AS17 -> 0
F18: =G18+H18 -> 0 | K18: =L18+M18 -> 0 | P18: =Q18+R18 -> 0 | U18: =V18+W18 -> 0 | Z18: =AA18+AB18 -> 0 | AE18: =AF18+AG18 -> 0 | AJ18: =AK18+AL18 -> 0 | AV18: =AU18-AR18 -> 0 | AW18: =AT18-AS18 -> 0
A19: ='IA-SI TANKER'!B8 -> Bright Future | B19: Ashwin | C19: Port | D19: 45466 | E19: 45466 | F19: =G19+H19 -> 5 | G19: 1 | H19: 4 | I19: 45466 | J19: 45466 | K19: =L19+M19 -> 5 | L19: 0 | M19: 5 | N19: 45466 | O19: 45466 | P19: =Q19+R19 -> 4 | Q19: 0 | R19: 4 | U19: =V19+W19 -> 0 | Z19: =AA19+AB19 -> 0 | AC19: 45466 | AD19: 45466 | AE19: =AF19+AG19 -> 0 | AF19: 0 | AG19: 0 | AJ19: =AK19+AL19 -> 0 | AP19: Mumbai | AQ19: Vadinar | AR19: 45463 | AS19: 45463 | AT19: 45466 | AU19: 45466 | AV19: =AU19-AR19 -> 3 | AW19: =AT19-AS19 -> 3
F20: =G20+H20 -> 0 | K20: =L20+M20 -> 0 | P20: =Q20+R20 -> 0 | U20: =V20+W20 -> 0 | Z20: =AA20+AB20 -> 0 | AE20: =AF20+AG20 -> 0 | AJ20: =AK20+AL20 -> 0 | AV20: =AU20-AR20 -> 0 | AW20: =AT20-AS20 -> 0
F21: =G21+H21 -> 0 | K21: =L21+M21 -> 0 | P21: =Q21+R21 -> 0 | U21: =V21+W21 -> 0 | Z21: =AA21+AB21 -> 0 | AE21: =AF21+AG21 -> 0 | AJ21: =AK21+AL21 -> 0 | AV21: =AU21-AR21 -> 0 | AW21: =AT21-AS21 -> 0
F22: =G22+H22 -> 0 | K22: =L22+M22 -> 0 | P22: =Q22+R22 -> 0 | U22: =V22+W22 -> 0 | Z22: =AA22+AB22 -> 0 | AE22: =AF22+AG22 -> 0 | AJ22: =AK22+AL22 -> 0 | AV22: =AU22-AR22 -> 0 | AW22: =AT22-AS22 -> 0
A23: ='IA-SI TANKER'!B9 -> Cielo di Houston | B23: Naveen | C23: Port/Navigation | D23: 09.10.2024 | E23: 09.10.2024 | F23: =G23+H23 -> 4 | G23: 0 | H23: 4 | I23: 09.10.2024 | J23: 09.10.2024 | K23: =L23+M23 -> 4 | L23: 0 | M23: 4 | N23: 09.10.2024 | O23: 09.10.2024 | P23: =Q23+R23 -> 2 | Q23: 0 | R23: 2 | S23: 09.10.2024 | T23: 09.10.2024 | U23: =V23+W23 -> 1 | V23: 0 | W23: 1 | X23: 09.10.2024 | Y23: 09.10.2024 | Z23: =AA23+AB23 -> 2 | AA23: 0 | AB23: 2 | AC23: 09.10.2024 | AD23: 09.10.2024 | AE23: =AF23+AG23 -> 0 | AF23: 0 | AG23: 0 | AH23: 09.10.2024 | AI23: 09.10.2024 | AJ23: =AK23+AL23 -> 0 | AK23: 0 | AL23: 0 | AM23: 09.10.2024 | AN23: 02.10.2024 | AO23: Viva Australia | AP23: Singapore | AQ23: Singapore | AR23: 45566 | AS23: 45566 | AT23: 45575 | AU23: 45575 | AV23: =AU23-AR23 -> 9 | AW23: =AT23-AS23 -> 9
B24: Jay | C24: Port | D24: 45302 | E24: 45302 | F24: =G24+H24 -> 2 | G24: 0 | H24: 2 | I24: 45302 | J24: 45302 | K24: =L24+M24 -> 2 | L24: 0 | M24: 2 | P24: =Q24+R24 -> 0 | U24: =V24+W24 -> 0 | Z24: =AA24+AB24 -> 0 | AC24: 45302 | AD24: 45302 | AE24: =AF24+AG24 -> 0 | AJ24: =AK24+AL24 -> 0 | AP24: Shanghai | AQ24: Shanghai | AR24: 45299 | AS24: 45299 | AT24: 45302 | AU24: 45302 | AV24: =AU24-AR24 -> 3 | AW24: =AT24-AS24 -> 3
F25: =G25+H25 -> 0 | K25: =L25+M25 -> 0 | P25: =Q25+R25 -> 0 | U25: =V25+W25 -> 0 | Z25: =AA25+AB25 -> 0 | AE25: =AF25+AG25 -> 0 | AJ25: =AK25+AL25 -> 0 | AV25: =AU25-AR25 -> 0 | AW25: =AT25-AS25 -> 0
F26: =G26+H26 -> 0 | K26: =L26+M26 -> 0 | P26: =Q26+R26 -> 0 | U26: =V26+W26 -> 0 | Z26: =AA26+AB26 -> 0 | AE26: =AF26+AG26 -> 0 | AJ26: =AK26+AL26 -> 0 | AV26: =AU26-AR26 -> 0 | AW26: =AT26-AS26 -> 0
A27: ='IA-SI TANKER'!B10 -> Cielo Rosso | B27: Naveen | C27: Port | D27: 14.05.2024 | E27: 14.05.2024 | F27: =G27+H27 -> 2 | G27: 0 | H27: 2 | I27: 14.05.2024 | J27: 14.05.2024 | K27: =L27+M27 -> 2 | L27: 0 | M27: 2 | P27: =Q27+R27 -> 0 | U27: =V27+W27 -> 0 | Z27: =AA27+AB27 -> 0 | AC27: 14.05.2024 | AD27: 14.05.2024 | AE27: =AF27+AG27 -> 0 | AF27: 0 | AG27: 0 | AJ27: =AK27+AL27 -> 0 | AP27: Sikka | AQ27: Sikka | AR27: 45423 | AS27: 45423 | AT27: 45426 | AU27: 45426 | AV27: =AU27-AR27 -> 3 | AW27: =AT27-AS27 -> 3
B28: Jay | C28: Port | D28: 04.12.2024 | E28: 4.12.2024 | F28: =G28+H28 -> 3 | G28: 0 | H28: 3 | I28: 4.12.2024 | J28: 4.12.2024 | K28: =L28+M28 -> 4 | L28: 0 | M28: 4 | N28: 04.12.2024 | O28: 04.12.2024 | P28: =Q28+R28 -> 1 | Q28: 0 | R28: 1 | U28: =V28+W28 -> 0 | X28: 04.12.2024 | Y28: 04.12.2024 | Z28: =AA28+AB28 -> 0 | AA28: 0 | AB28: 0 | AC28: 4.12.2024 | AD28: 4.12.2024 | AE28: =AF28+AG28 -> 0 | AF28: 0 | AG28: 0 | AH28: 04.12.2024 | AI28: 04.12.2024 | AJ28: =AK28+AL28 -> 2 | AK28: 0 | AL28: 2 | AP28: Long Beach | AQ28: Long Beach | AR28: 45625 | AS28: 45627 | AT28: 45630 | AU28: 45631 | AV28: =AU28-AR28 -> 6 | AW28: =AT28-AS28 -> 3
F29: =G29+H29 -> 0 | K29: =L29+M29 -> 0 | P29: =Q29+R29 -> 0 | U29: =V29+W29 -> 0 | Z29: =AA29+AB29 -> 0 | AE29: =AF29+AG29 -> 0 | AJ29: =AK29+AL29 -> 0 | AV29: =AU29-AR29 -> 0 | AW29: =AT29-AS29 -> 0
F30: =G30+H30 -> 0 | K30: =L30+M30 -> 0 | P30: =Q30+R30 -> 0 | U30: =V30+W30 -> 0 | Z30: =AA30+AB30 -> 0 | AE30: =AF30+AG30 -> 0 | AJ30: =AK30+AL30 -> 0 | AV30: =AU30-AR30 -> 0 | AW30: =AT30-AS30 -> 0
A31: ='IA-SI TANKER'!B11 -> Clearocean Maria | B31: Avish | C31: Port | D31: 20.09.2024 | E31: 20.09.2024 | F31: =G31+H31 -> 6 | G31: 0 | H31: 6 | I31: 20.09.2024 | J31: 20.09.2024 | K31: =L31+M31 -> 6 | L31: 0 | M31: 6 | N31: 20.09.2024 | O31: 20.09.2024 | P31: =Q31+R31 -> 3 | Q31: 0 | R31: 3 | U31: =V31+W31 -> 0 | Z31: =AA31+AB31 -> 0 | AC31: 20.09.2024 | AD31: 20.09.2024 | AE31: =AF31+AG31 -> 0 | AF31: 0 | AG31: 0 | AJ31: =AK31+AL31 -> 0 | AP31: Singapore | AQ31: Singapore | AR31: 45552 | AS31: 45552 | AT31: 45555 | AU31: 45552 | AV31: =AU31-AR31 -> 0 | AW31: =AT31-AS31 -> 3
F32: =G32+H32 -> 0 | K32: =L32+M32 -> 0 | P32: =Q32+R32 -> 0 | U32: =V32+W32 -> 0 | Z32: =AA32+AB32 -> 0 | AE32: =AF32+AG32 -> 0 | AJ32: =AK32+AL32 -> 0 | AV32: =AU32-AR32 -> 0 | AW32: =AT32-AS32 -> 0
F33: =G33+H33 -> 0 | K33: =L33+M33 -> 0 | P33: =Q33+R33 -> 0 | U33: =V33+W33 -> 0 | Z33: =AA33+AB33 -> 0 | AE33: =AF33+AG33 -> 0 | AJ33: =AK33+AL33 -> 0 | AV33: =AU33-AR33 -> 0 | AW33: =AT33-AS33 -> 0
F34: =G34+H34 -> 0 | K34: =L34+M34 -> 0 | P34: =Q34+R34 -> 0 | U34: =V34+W34 -> 0 | Z34: =AA34+AB34 -> 0 | AE34: =AF34+AG34 -> 0 | AJ34: =AK34+AL34 -> 0 | AV34: =AU34-AR34 -> 0 | AW34: =AT34-AS34 -> 0
A35: ='IA-SI TANKER'!B12 -> Clearocean Mary | B35: Rajneesh | C35: Port/Navigation | D35: 26.11.2024 | E35: 26.11.2024 | F35: =G35+H35 -> 4 | G35: 0 | H35: 4 | I35: 26.11.2024 | J35: 26.11.2024 | K35: =L35+M35 -> 7 | L35: 1 | M35: 6 | N35: 26.11.2024 | O35: 26.11.2024 | P35: =Q35+R35 -> 7 | Q35: 0 | R35: 7 | S35: 26.11.2024 | T35: 26.11.2024 | U35: =V35+W35 -> 6 | V35: 0 | W35: 6 | X35: 26.11.2024 | Y35: 26.11.2024 | Z35: =AA35+AB35 -> 4 | AA35: 0 | AB35: 4 | AC35: 26.11.2024 | AD35: 26.11.2024 | AE35: =AF35+AG35 -> 0 | AF35: 0 | AG35: 0 | AH35: 26.11.2024 | AI35: 26.11.2024 | AJ35: =AK35+AL35 -> 4 | AK35: 0 | AL35: 4 | AM35: 26.11.2024 | AP35: Lake charles | AQ35: San Nicholas | AR35: 45610 | AS35: 45610 | AT35: 45622 | AU35: 45624 | AV35: =AU35-AR35 -> 14 | AW35: =AT35-AS35 -> 12
F36: =G36+H36 -> 0 | K36: =L36+M36 -> 0 | P36: =Q36+R36 -> 0 | U36: =V36+W36 -> 0 | Z36: =AA36+AB36 -> 0 | AE36: =AF36+AG36 -> 0 | AJ36: =AK36+AL36 -> 0 | AV36: =AU36-AR36 -> 0 | AW36: =AT36-AS36 -> 0
F37: =G37+H37 -> 0 | K37: =L37+M37 -> 0 | P37: =Q37+R37 -> 0 | U37: =V37+W37 -> 0 | Z37: =AA37+AB37 -> 0 | AE37: =AF37+AG37 -> 0 | AJ37: =AK37+AL37 -> 0 | AV37: =AU37-AR37 -> 0 | AW37: =AT37-AS37 -> 0
F38: =G38+H38 -> 0 | K38: =L38+M38 -> 0 | P38: =Q38+R38 -> 0 | U38: =V38+W38 -> 0 | Z38: =AA38+AB38 -> 0 | AE38: =AF38+AG38 -> 0 | AJ38: =AK38+AL38 -> 0 | AV38: =AU38-AR38 -> 0 | AW38: =AT38-AS38 -> 0
A39: ='IA-SI TANKER'!B13 -> Clearocean Mathilde | B39: Naveen | C39: Port/Navigation | D39: 31.07.2024 | E39: 31.07.2024 | F39: =G39+H39 -> 3 | G39: 0 | H39: 3 | I39: 31.07.2024 | J39: 31.07.2024 | K39: =L39+M39 -> 3 | L39: 0 | M39: 3 | N39: 31.07.2024 | O39: 31.07.2024 | P39: =Q39+R39 -> 2 | Q39: 0 | R39: 2 | S39: 31.07.2024 | T39: 31.07.2024 | U39: =V39+W39 -> 2 | V39: 0 | W39: 2 | X39: 31.07.2024 | Y39: 31.07.2024 | Z39: =AA39+AB39 -> 2 | AA39: 0 | AB39: 2 | AC39: 31.07.2024 | AD39: 31.07.2024 | AE39: =AF39+AG39 -> 0 | AF39: 0 | AG39: 0 | AH39: 31.07.2024 | AI39: 31.07.2024 | AJ39: =AK39+AL39 -> 2 | AK39: 0 | AL39: 2 | AM39: 31.07.2024 | AP39: Manzanillo | AQ39: Mazatlan | AR39: 45496 | AS39: 45496 | AT39: 45504 | AU39: 45507 | AV39: =AU39-AR39 -> 11 | AW39: =AT39-AS39 -> 8
F40: =G40+H40 -> 0 | K40: =L40+M40 -> 0 | P40: =Q40+R40 -> 0 | U40: =V40+W40 -> 0 | Z40: =AA40+AB40 -> 0 | AE40: =AF40+AG40 -> 0 | AJ40: =AK40+AL40 -> 0 | AV40: =AU40-AR40 -> 0 | AW40: =AT40-AS40 -> 0
...

Sheet Int.Aud. Category
C1: INTERNAL AUDIT CATEGORY OBSERVATION
A9: General Fleet | B9: 1st Quarter | C9: 2nd Quarter | D9: 3rd Quarter | E9: 4th Quarter | F9: Total | Q9: Tanker | R9: 1st Quarter | S9: 2nd Quarter | T9: 3rd Quarter | U9: 4th Quarter | W9: Total | AF9: DRY | AG9: 1st Quarter | AH9: 2nd Quarter | AI9: 3rd Quarter | AJ9: 4th Quarter | AM9: Total
A10: No. Vess. | B10: 34 | C10: 34 | D10: 35 | E10: 37 | K10: # | Q10: No. Vess. | R10: 25 | S10: 25 | T10: 25 | U10: 26 | AF10: No. Vess. | AG10: 9 | AH10: 9 | AI10: 10 | AJ10: 11
A11: No. Aud. | B11: 8 | C11: =Q61 -> 10 | D11: =AF61 -> 13 | E11: =AU61 -> 10 | F11: =SUM(B11:E11) -> 41 | Q11: No. Aud. | R11: =SUM(B19:B48) -> 7 | S11: =SUM(Q19:Q48) -> 9 | T11: =SUM(AF19:AF48) -> 7 | U11: =SUM(AU19:AU48) -> 8 | W11: =SUM(R11:U11) -> 31 | AF11: No. Aud. | AG11: =SUM(B49:B60) -> 1 | AH11: =SUM(Q49:Q60) -> 1 | AI11: =SUM(AF49:AF60) -> 6 | AJ11: =SUM(AU49:AU60) -> 2 | AM11: =SUM(AG11:AL11) -> 10
A12: Def. | B12: =D61 -> 22 | C12: =S61 -> 44 | D12: =AH61 -> 57 | E12: =AW61 -> 46 | F12: =SUM(B12:E12) -> 169 | Q12: Def. | R12: =SUM(D19:D48) -> 19 | S12: =SUM(S19:S48) -> 39 | T12: =SUM(AH19:AH48) -> 29 | U12: =SUM(AW19:AW48) -> 36 | W12: =SUM(R12:V12) -> 123 | AF12: Def. | AG12: =SUM(D49:D60) -> 3 | AH12: =SUM(S49:S60) -> 5 | AI12: =SUM(AH49:AH60) -> 28 | AJ12: =SUM(AW49:AW60) -> 10 | AM12: =SUM(AG12:AL12) -> 46
A13: Def x Insp. | B13: =E61 -> 2.75 | C13: =T61 -> 4.4 | D13: =AI61 -> 4.3846154 | E13: =AX61 -> 4.6 | F13: =F12/F11 -> 4.1219512 | Q13: Def x Insp. | R13: =R12/R11 -> 2.7142857 | S13: =S12/S11 -> 4.3333333 | T13: =T12/T11 -> 4.1428571 | U13: =U12/U11 -> 4.5 | W13: =W12/W11 -> 3.9677419 | AF13: Def x Insp. | AG13: =AG12/AG11 -> 3 | AH13: =AH12/AH11 -> 5 | AI13: =AI12/AI11 -> 4.6666667 | AJ13: =AJ12/AJ11 -> 5 | AM13: =AM12/AM11 -> 4.6
A16: Fill in fields white and grey only
B17: 1st quarter | Q17: 2nd quarter | AF17: 3rd quarter | AU17: 4th quarter | BJ17: Total
B18: No. Insp. | D18: Def. | E18: Def x Insp | F18: 2 | G18: 3 | H18: 4 | I18: 5 | J18: 6 | K18: 7 | L18: 8 | M18: 9 | N18: 10 | O18: 11 | P18: 12 | Q18: No. Insp. | S18: Def. | T18: Def x Insp | U18: 2 | V18: 3 | W18: 4 | X18: 5 | Y18: 6 | Z18: 7 | AA18: 8 | AB18: 9 | AC18: 10 | AD18: 11 | AE18: 12 | AF18: No. Insp. | AH18: Def. | AI18: Def x Insp | AJ18: 2 | AK18: 3 | AL18: 4 | AM18: 5 | AN18: 6 | AO18: 7 | AP18: 8 | AQ18: 9 | AR18: 10 | AS18: 11 | AT18: 12 | AU18: No. Insp. | AW18: Def. | AX18: Def x Insp | AY18: 2 | AZ18: 3 | BA18: 4 | BB18: 5 | BC18: 6 | BD18: 7 | BE18: 8 | BF18: 9 | BG18: 10 | BH18: 11 | BI18: 12 | BJ18: No. Insp. | BL18: Def. | BM18: Def x Insp
A19: ='IA-SI TANKER'!B4 -> Alpine Pembroke (Sold) | D19: =SUM(F19:P19) -> 0 | E19: =(D19/B19) -> #DIV/0! | S19: =SUM(U19:AE19) -> 0 | T19: =(S19/Q19) -> #DIV/0! | AH19: =SUM(AJ19:AT19) -> 0 | AI19: =(AH19/AF19) -> #DIV/0! | AW19: =SUM(AY19:BI19) -> 0 | AX19: =(AW19/AU19) -> #DIV/0! | BJ19: =SUM(B19+Q19+AF19+AU19) -> 0 | BL19: =SUM(D19,S19,AH19,AW19) -> 0 | BM19: =(BL19/BJ19) -> #DIV/0!
A20: ='IA-SI TANKER'!B5 -> Alpine Pioneer (Sold) | D20: =SUM(F20:P20) -> 0 | E20: =(D20/B20) -> #DIV/0! | S20: =SUM(U20:AE20) -> 0 | T20: =(S20/Q20) -> #DIV/0! | AH20: =SUM(AJ20:AT20) -> 0 | AI20: =(AH20/AF20) -> #DIV/0! | AW20: =SUM(AY20:BI20) -> 0 | AX20: =(AW20/AU20) -> #DIV/0! | BJ20: =SUM(B20+Q20+AF20+AU20) -> 0 | BL20: =SUM(D20,S20,AH20,AW20) -> 0 | BM20: =(BL20/BJ20) -> #DIV/0!
A21: ='IA-SI TANKER'!B6 -> Bagheera | D21: =SUM(F21:P21) -> 0 | E21: =(D21/B21) -> #DIV/0! | Q21: 1 | S21: =SUM(U21:AE21) -> 5 | T21: =(S21/Q21) -> 5 | U21: 3 | Y21: 2 | AH21: =SUM(AJ21:AT21) -> 0 | AI21: =(AH21/AF21) -> #DIV/0! | AW21: =SUM(AY21:BI21) -> 0 | AX21: =(AW21/AU21) -> #DIV/0! | BJ21: =SUM(B21+Q21+AF21+AU21) -> 1 | BL21: =SUM(D21,S21,AH21,AW21) -> 5 | BM21: =(BL21/BJ21) -> 5
A22: ='IA-SI TANKER'!B7 -> Bantry Bay | D22: =SUM(F22:P22) -> 0 | E22: =(D22/B22) -> #DIV/0! | S22: =SUM(U22:AE22) -> 0 | T22: =(S22/Q22) -> #DIV/0! | AF22: 1 | AH22: =SUM(AJ22:AT22) -> 6 | AI22: =(AH22/AF22) -> 6 | AM22: 5 | AR22: 1 | AW22: =SUM(AY22:BI22) -> 0 | AX22: =(AW22/AU22) -> #DIV/0! | BJ22: =SUM(B22+Q22+AF22+AU22) -> 1 | BL22: =SUM(D22,S22,AH22,AW22) -> 6 | BM22: =(BL22/BJ22) -> 6
A23: ='IA-SI TANKER'!B8 -> Bright Future | D23: =SUM(F23:P23) -> 0 | E23: =(D23/B23) -> #DIV/0! | Q23: 1 | S23: =SUM(U23:AE23) -> 5 | T23: =(S23/Q23) -> 5 | U23: 1 | V23: 1 | X23: 1 | AC23: 2 | AH23: =SUM(AJ23:AT23) -> 0 | AI23: =(AH23/AF23) -> #DIV/0! | AW23: =SUM(AY23:BI23) -> 0 | AX23: =(AW23/AU23) -> #DIV/0! | BJ23: =SUM(B23+Q23+AF23+AU23) -> 1 | BL23: =SUM(D23,S23,AH23,AW23) -> 5 | BM23: =(BL23/BJ23) -> 5
A24: ='IA-SI TANKER'!B9 -> Cielo di Houston | B24: 1 | D24: =SUM(F24:P24) -> 2 | E24: =(D24/B24) -> 2 | F24: 1 | I24: 1 | S24: =SUM(U24:AE24) -> 0 | T24: =(S24/Q24) -> #DIV/0! | AH24: =SUM(AJ24:AT24) -> 0 | AI24: =(AH24/AF24) -> #DIV/0! | AU24: 1 | AW24: =SUM(AY24:BI24) -> 4 | AX24: =(AW24/AU24) -> 4 | BB24: 1 | BH24: 3 | BJ24: =SUM(B24+Q24+AF24+AU24) -> 2 | BL24: =SUM(D24,S24,AH24,AW24) -> 6 | BM24: =(BL24/BJ24) -> 3
A25: ='IA-SI TANKER'!B10 -> Cielo Rosso | D25: =SUM(F25:P25) -> 0 | E25: =(D25/B25) -> #DIV/0! | Q25: 1 | S25: =SUM(U25:AE25) -> 2 | T25: =(S25/Q25) -> 2 | X25: 2 | AH25: =SUM(AJ25:AT25) -> 0 | AI25: =(AH25/AF25) -> #DIV/0! | AU25: 1 | AW25: =SUM(AY25:BI25) -> 3 | AX25: =(AW25/AU25) -> 3 | BB25: 3 | BJ25: =SUM(B25+Q25+AF25+AU25) -> 2 | BL25: =SUM(D25,S25,AH25,AW25) -> 5 | BM25: =(BL25/BJ25) -> 2.5
A26: ='IA-SI TANKER'!B11 -> Clearocean Maria | D26: =SUM(F26:P26) -> 0 | E26: =(D26/B26) -> #DIV/0! | S26: =SUM(U26:AE26) -> 0 | T26: =(S26/Q26) -> #DIV/0! | AF26: 1 | AH26: =SUM(AJ26:AT26) -> 6 | AI26: =(AH26/AF26) -> 6 | AJ26: 2 | AM26: 2 | AP26: 2 | AW26: =SUM(AY26:BI26) -> 0 | AX26: =(AW26/AU26) -> #DIV/0! | BJ26: =SUM(B26+Q26+AF26+AU26) -> 1 | BL26: =SUM(D26,S26,AH26,AW26) -> 6 | BM26: =(BL26/BJ26) -> 6
A27: ='IA-SI TANKER'!B12 -> Clearocean Mary | D27: =SUM(F27:P27) -> 0 | E27: =(D27/B27) -> #DIV/0! | S27: =SUM(U27:AE27) -> 0 | T27: =(S27/Q27) -> #DIV/0! | AH27: =SUM(AJ27:AT27) -> 0 | AI27: =(AH27/AF27) -> #DIV/0! | AU27: 1 | AW27: =SUM(AY27:BI27) -> 4 | AX27: =(AW27/AU27) -> 4 | BB27: 1 | BE27: 1 | BG27: 1 | BH27: 1 | BJ27: =SUM(B27+Q27+AF27+AU27) -> 1 | BL27: =SUM(D27,S27,AH27,AW27) -> 4 | BM27: =(BL27/BJ27) -> 4
A28: ='IA-SI TANKER'!B13 -> Clearocean Mathilde | D28: =SUM(F28:P28) -> 0 | E28: =(D28/B28) -> #DIV/0! | S28: =SUM(U28:AE28) -> 0 | T28: =(S28/Q28) -> #DIV/0! | AF28: 1 | AH28: =SUM(AJ28:AT28) -> 3 | AI28: =(AH28/AF28) -> 3 | AM28: 2 | AN28: 1 | AW28: =SUM(AY28:BI28) -> 0 | AX28: =(AW28/AU28) -> #DIV/0! | BJ28: =SUM(B28+Q28+AF28+AU28) -> 1 | BL28: =SUM(D28,S28,AH28,AW28) -> 3 | BM28: =(BL28/BJ28) -> 3
A29: ='IA-SI TANKER'!B14 -> Clearocean Music | B29: 0 | D29: =SUM(F29:P29) -> 0 | E29: =(D29/B29) -> #DIV/0! | L29: 0 | S29: =SUM(U29:AE29) -> 0 | T29: =(S29/Q29) -> #DIV/0! | AF29: 1 | AH29: 3 | AI29: =(AH29/AF29) -> 3 | AM29: 3 | AW29: =SUM(AY29:BI29) -> 0 | AX29: =(AW29/AU29) -> #DIV/0! | BJ29: =SUM(B29+Q29+AF29+AU29) -> 1 | BL29: =SUM(D29,S29,AH29,AW29) -> 3 | BM29: =(BL29/BJ29) -> 3
A30: ='IA-SI TANKER'!B15 -> Rui Fu Xing (Glenda Melanie) | D30: =SUM(F30:P30) -> 0 | E30: =(D30/B30) -> #DIV/0! | Q30: 1 | S30: =SUM(U30:AE30) -> 4 | T30: =(S30/Q30) -> 4 | X30: 3 | Y30: 1 | AH30: =SUM(AJ30:AT30) -> 0 | AI30: =(AH30/AF30) -> #DIV/0! | AW30: =SUM(AY30:BI30) -> 0 | AX30: =(AW30/AU30) -> #DIV/0! | BJ30: =SUM(B30+Q30+AF30+AU30) -> 1 | BL30: =SUM(D30,S30,AH30,AW30) -> 4 | BM30: =(BL30/BJ30) -> 4
A31: ='IA-SI TANKER'!B16 -> Glenda Melissa | B31: 1 | D31: =SUM(F31:P31) -> 4 | E31: =(D31/B31) -> 4 | H31: 2 | I31: 1 | L31: 1 | S31: =SUM(U31:AE31) -> 0 | T31: =(S31/Q31) -> #DIV/0! | AH31: =SUM(AJ31:AT31) -> 0 | AI31: =(AH31/AF31) -> #DIV/0! | AW31: =SUM(AY31:BI31) -> 0 | AX31: =(AW31/AU31) -> #DIV/0! | BJ31: =SUM(B31+Q31+AF31+AU31) -> 1 | BL31: =SUM(D31,S31,AH31,AW31) -> 4 | BM31: =(BL31/BJ31) -> 4
A32: ='IA-SI TANKER'!B17 -> Glenda Melody | D32: =SUM(F32:P32) -> 0 | E32: =(D32/B32) -> #DIV/0! | Q32: 1 | S32: =SUM(U32:AE32) -> 6 | T32: =(S32/Q32) -> 6 | U32: 1 | V32: 1 | W32: 1 | X32: 2 | Y32: 1 | AH32: =SUM(AJ32:AT32) -> 0 | AI32: =(AH32/AF32) -> #DIV/0! | AW32: =SUM(AY32:BI32) -> 0 | AX32: =(AW32/AU32) -> #DIV/0! | BJ32: =SUM(B32+Q32+AF32+AU32) -> 1 | BL32: =SUM(D32,S32,AH32,AW32) -> 6 | BM32: =(BL32/BJ32) -> 6
A33: ='IA-SI TANKER'!B18 -> Glenda Meryl | B33: 1 | D33: =SUM(F33:P33) -> 3 | E33: =(D33/B33) -> 3 | H33: 1 | I33: 1 | O33: 1 | S33: =SUM(U33:AE33) -> 0 | T33: =(S33/Q33) -> #DIV/0! | AH33: =SUM(AJ33:AT33) -> 0 | AI33: =(AH33/AF33) -> #DIV/0! | AU33: 1 | AW33: =SUM(AY33:BI33) -> 6 | AX33: =(AW33/AU33) -> 6 | AY33: 1 | BA33: 2 | BB33: 1 | BC33: 1 | BE33: 1 | BJ33: =SUM(B33+Q33+AF33+AU33) -> 2 | BL33: =SUM(D33,S33,AH33,AW33) -> 9 | BM33: =(BL33/BJ33) -> 4.5
A34: ='IA-SI TANKER'!B19 -> Herolds Bay | D34: =SUM(F34:P34) -> 0 | E34: =(D34/B34) -> #DIV/0! | S34: =SUM(U34:AE34) -> 0 | T34: =(S34/Q34) -> #DIV/0! | AH34: =SUM(AJ34:AT34) -> 0 | AI34: =(AH34/AF34) -> #DIV/0! | AU34: 1 | AW34: =SUM(AY34:BI34) -> 4 | AX34: =(AW34/AU34) -> 4 | BB34: 4 | BJ34: =SUM(B34+Q34+AF34+AU34) -> 1 | BL34: =SUM(D34,S34,AH34,AW34) -> 4 | BM34: =(BL34/BJ34) -> 4
A35: ='IA-SI TANKER'!B20 -> High Explorer | D35: =SUM(F35:P35) -> 0 | E35: =(D35/B35) -> #DIV/0! | S35: =SUM(U35:AE35) -> 0 | T35: =(S35/Q35) -> #DIV/0! | AF35: 1 | AH35: =SUM(AJ35:AT35) -> 5 | AI35: =(AH35/AF35) -> 5 | AL35: 1 | AM35: 3 | AQ35: 1 | AW35: =SUM(AY35:BI35) -> 0 | AX35: =(AW35/AU35) -> #DIV/0! | BJ35: =SUM(B35+Q35+AF35+AU35) -> 1 | BL35: =SUM(D35,S35,AH35,AW35) -> 5 | BM35: =(BL35/BJ35) -> 5
A36: ='IA-SI TANKER'!B21 -> High Mariner | D36: =SUM(F36:P36) -> 0 | E36: =(D36/B36) -> #DIV/0! | S36: =SUM(U36:AE36) -> 0 | T36: =(S36/Q36) -> #DIV/0! | AH36: =SUM(AJ36:AT36) -> 0 | AI36: =(AH36/AF36) -> #DIV/0! | AW36: =SUM(AY36:BI36) -> 0 | AX36: =(AW36/AU36) -> #DIV/0! | BJ36: =SUM(B36+Q36+AF36+AU36) -> 0 | BL36: =SUM(D36,S36,AH36,AW36) -> 0 | BM36: =(BL36/BJ36) -> #DIV/0!
A37: ='IA-SI TANKER'!B22 -> High Transporter | D37: =SUM(F37:P37) -> 0 | E37: =(D37/B37) -> #DIV/0! | S37: =SUM(U37:AE37) -> 0 | T37: =(S37/Q37) -> #DIV/0! | AH37: =SUM(AJ37:AT37) -> 0 | AI37: =(AH37/AF37) -> #DIV/0! | AU37: 1 | AW37: =SUM(AY37:BI37) -> 7 | AX37: =(AW37/AU37) -> 7 | BB37: 3 | BF37: 2 | BG37: 1 | BH37: 1 | BJ37: =SUM(B37+Q37+AF37+AU37) -> 1 | BL37: =SUM(D37,S37,AH37,AW37) -> 7 | BM37: =(BL37/BJ37) -> 7
A38: ='IA-SI TANKER'!B$23 -> Kalk Bay | D38: =SUM(F38:P38) -> 0 | E38: =(D38/B38) -> #DIV/0! | Q38: 1 | S38: =SUM(U38:AE38) -> 4 | T38: =(S38/Q38) -> 4 | X38: 4 | AH38: =SUM(AJ38:AT38) -> 0 | AI38: =(AH38/AF38) -> #DIV/0! | AW38: =SUM(AY38:BI38) -> 0 | AX38: =(AW38/AU38) -> #DIV/0! | BJ38: =SUM(B38+Q38+AF38+AU38) -> 1 | BL38: =SUM(D38,S38,AH38,AW38) -> 4 | BM38: =(BL38/BJ38) -> 4
A39: ='IA-SI TANKER'!B$24 -> Mossel Bay | B39: 1 | D39: =SUM(F39:P39) -> 5 | E39: =(D39/B39) -> 5 | I39: 5 | S39: =SUM(U39:AE39) -> 0 | T39: =(S39/Q39) -> #DIV/0! | AH39: =SUM(AJ39:AT39) -> 0 | AI39: =(AH39/AF39) -> #DIV/0! | AU39: 1 | AW39: =SUM(AY39:BI39) -> 5 | AX39: =(AW39/AU39) -> 5 | BB39: 4 | BC39: 1 | BJ39: =SUM(B39+Q39+AF39+AU39) -> 2 | BL39: =SUM(D39,S39,AH39,AW39) -> 10 | BM39: =(BL39/BJ39) -> 5
A40: ='IA-SI TANKER'!B25 -> Philotimos | D40: =SUM(F40:P40) -> 0 | E40: =(D40/B40) -> #DIV/0! | S40: =SUM(U40:AE40) -> 0 | T40: =(S40/Q40) -> #DIV/0! | AF40: 1 | AH40: =SUM(AJ40:AT40) -> 3 | AI40: =(AH40/AF40) -> 3 | AJ40: 1 | AM40: 1 | AN40: 1 | AW40: =SUM(AY40:BI40) -> 0 | AX40: =(AW40/AU40) -> #DIV/0! | BJ40: =SUM(B40+Q40+AF40+AU40) -> 1 | BL40: =SUM(D40,S40,AH40,AW40) -> 3 | BM40: =(BL40/BJ40) -> 3
A41: ='IA-SI TANKER'!B26 -> Philoxenia | B41: 1 | D41: =SUM(F41:P41) -> 2 | E41: =(D41/B41) -> 2 | G41: 1 | I41: 1 | S41: =SUM(U41:AE41) -> 0 | T41: =(S41/Q41) -> #DIV/0! | AH41: =SUM(AJ41:AT41) -> 0 | AI41: =(AH41/AF41) -> #DIV/0! | AU41: 1 | AW41: =SUM(AY41:BI41) -> 3 | AX41: =(AW41/AU41) -> 3 | BB41: 2 | BH41: 1 | BJ41: =SUM(B41+Q41+AF41+AU41) -> 2 | BL41: =SUM(D41,S41,AH41,AW41) -> 5 | BM41: =(BL41/BJ41) -> 2.5
A42: ='IA-SI TANKER'!B27 -> PNX Conqueror | B42: 1 | D42: =SUM(F42:P42) -> 2 | E42: =(D42/B42) -> 2 | H42: 1 | I42: 1 | S42: =SUM(U42:AE42) -> 0 | T42: =(S42/Q42) -> #DIV/0! | AH42: =SUM(AJ42:AT42) -> 0 | AI42: =(AH42/AF42) -> #DIV/0! | AW42: =SUM(AY42:BI42) -> 0 | AX42: =(AW42/AU42) -> #DIV/0! | BJ42: =SUM(B42+Q42+AF42+AU42) -> 1 | BL42: =SUM(D42,S42,AH42,AW42) -> 2 | BM42: =(BL42/BJ42) -> 2
A43: ='IA-SI TANKER'!B28 -> PS Tokyo (Gone) | D43: =SUM(F43:P43) -> 0 | E43: =(D43/B43) -> #DIV/0! | S43: =SUM(U43:AE43) -> 0 | T43: =(S43/Q43) -> #DIV/0! | AH43: =SUM(AJ43:AT43) -> 0 | AI43: =(AH43/AF43) -> #DIV/0! | AW43: =SUM(AY43:BI43) -> 0 | AX43: =(AW43/AU43) -> #DIV/0! | BJ43: =SUM(B43+Q43+AF43+AU43) -> 0 | BL43: =SUM(D43,S43,AH43,AW43) -> 0 | BM43: =(BL43/BJ43) -> #DIV/0!
A44: ='IA-SI TANKER'!B29 -> PS Vancouver | D44: =SUM(F44:P44) -> 0 | E44: =(D44/B44) -> #DIV/0! | S44: =SUM(U44:AE44) -> 0 | T44: =(S44/Q44) -> #DIV/0! | AF44: 1 | AH44: 3 | AI44: =(AH44/AF44) -> 3 | AM44: 3 | AW44: =SUM(AY44:BI44) -> 0 | AX44: =(AW44/AU44) -> #DIV/0! | BJ44: =SUM(B44+Q44+AF44+AU44) -> 1 | BL44: =SUM(D44,S44,AH44,AW44) -> 3 | BM44: =(BL44/BJ44) -> 3
A45: ='IA-SI TANKER'!B30 -> Table Bay | D45: =SUM(F45:P45) -> 0 | E45: =(D45/B45) -> #DIV/0! | Q45: 1 | S45: =SUM(U45:AE45) -> 3 | T45: =(S45/Q45) -> 3 | U45: 2 | X45: 1 | AH45: =SUM(AJ45:AT45) -> 0 | AI45: =(AH45/AF45) -> #DIV/0! | AW45: =SUM(AY45:BI45) -> 0 | AX45: =(AW45/AU45) -> #DIV/0! | BJ45: =SUM(B45+Q45+AF45+AU45) -> 1 | BL45: =SUM(D45,S45,AH45,AW45) -> 3 | BM45: =(BL45/BJ45) -> 3
A46: ='IA-SI TANKER'!B31 -> Rui Fu Sheng | D46: =SUM(F46:P46) -> 0 | E46: =(D46/B46) -> #DIV/0! | Q46: 1 | S46: =SUM(U46:AE46) -> 6 | T46: =(S46/Q46) -> 6 | U46: 1 | X46: 2 | Y46: 1 | AC46: 1 | AD46: 1 | AH46: =SUM(AJ46:AT46) -> 0 | AI46: =(AH46/AF46) -> #DIV/0! | AW46: =SUM(AY46:BI46) -> 0 | AX46: =(AW46/AU46) -> #DIV/0! | BJ46: =SUM(B46+Q46+AF46+AU46) -> 1 | BL46: =SUM(D46,S46,AH46,AW46) -> 6 | BM46: =(BL46/BJ46) -> 6
A47: ='IA-SI TANKER'!B32 -> Vialli | B47: 1 | D47: =SUM(F47:P47) -> 1 | E47: =(D47/B47) -> 1 | I47: 1 | S47: =SUM(U47:AE47) -> 0 | T47: =(S47/Q47) -> #DIV/0! | AH47: =SUM(AJ47:AT47) -> 0 | AI47: =(AH47/AF47) -> #DIV/0! | AW47: =SUM(AY47:BI47) -> 0 | AX47: =(AW47/AU47) -> #DIV/0! | BJ47: =SUM(B47+Q47+AF47+AU47) -> 1 | BL47: =SUM(D47,S47,AH47,AW47) -> 1 | BM47: =(BL47/BJ47) -> 1
A48: ='IA-SI TANKER'!B33 -> Victoria Bay | D48: =SUM(F48:P48) -> 0 | E48: =(D48/B48) -> #DIV/0! | Q48: 1 | S48: =SUM(U48:AE48) -> 4 | T48: =(S48/Q48) -> 4 | U48: 1 | X48: 3 | AH48: =SUM(AJ48:AT48) -> 0 | AI48: =(AH48/AF48) -> #DIV/0! | AW48: =SUM(AY48:BI48) -> 0 | AX48: =(AW48/AU48) -> #DIV/0! | BJ48: =SUM(B48+Q48+AF48+AU48) -> 1 | BL48: =SUM(D48,S48,AH48,AW48) -> 4 | BM48: =(BL48/BJ48) -> 4
A49: =' IA-SI DRY'!B4 -> Cielo di Valparaiso | D49: =SUM(F49:P49) -> 0 | E49: =(D49/B49) -> #DIV/0! | S49: =SUM(U49:AE49) -> 0 | T49: =(S49/Q49) -> #DIV/0! | AH49: =SUM(AJ49:AT49) -> 0 | AI49: =(AH49/AF49) -> #DIV/0! | AW49: =SUM(AY49:BI49) -> 0 | AX49: =(AW49/AU49) -> #DIV/0! | BJ49: =SUM(B49+Q49+AF49+AU49) -> 0 | BL49: =SUM(D49,S49,AH49,AW49) -> 0 | BM49: =(BL49/BJ49) -> #DIV/0!
...

Sheet Saf.Insp.category
C1: SAFETY INSPECTION CATEGORY OBSERVATION
A9: General Fleet | B9: 1st Quarter | C9: 2nd Quarter | D9: 3rd Quarter | E9: 4th Quarter | F9: Total | Q9: Tanker | S9: 1st Quarter | T9: 2nd Quarter | U9: 3rd Quarter | W9: 4th Quarter | Y9: Total | AF9: dry | AG9: 1st Quarter | AH9: 2nd Quarter | AI9: 3rd Quarter | AJ9: 4th Quarter | AM9: Total
A10: No. Vess. | B10: 34 | C10: 34 | D10: 35 | E10: 37 | Q10: No. Vess. | S10: 25 | T10: 25 | U10: 25 | W10: 26 | AF10: No. Vess. | AG10: 9 | AH10: 9 | AI10: 10 | AJ10: 11
A11: No. Insp. | B11: =B61 -> 7 | C11: =Q61 -> 7 | D11: =AF61 -> 9 | E11: =AU61 -> 11 | F11: =SUM(B11:E11) -> 34 | Q11: No. Insp. | S11: =SUM(B19:B48) -> 7 | T11: =SUM(Q19:Q48) -> 7 | U11: =SUM(AF19:AF48) -> 6 | W11: =SUM(AU19:AU48) -> 9 | Y11: =SUM(S11:X11) -> 29 | AF11: No. Insp. | AG11: =SUM(B49:B60) -> 0 | AH11: =SUM(Q49:Q60) -> 0 | AI11: =SUM(AF49:AF60) -> 3 | AJ11: =SUM(AU49:AU60) -> 2 | AM11: =SUM(AG11:AL11) -> 5
A12: Def. | B12: =D61 -> 26 | C12: =S61 -> 31 | D12: =AH61 -> 51 | E12: =AW61 -> 62 | F12: =SUM(B12:E12) -> 170 | Q12: Def. | S12: =SUM(D19:D48) -> 26 | T12: =SUM(S19:S48) -> 31 | U12: =SUM(AH19:AH48) -> 34 | W12: =SUM(AW19:AW48) -> 53 | Y12: =SUM(S12:X12) -> 144 | AF12: Def. | AG12: =SUM(D49:D60) -> 0 | AH12: =SUM(S49:S60) -> 0 | AI12: =SUM(AH49:AH60) -> 17 | AJ12: =SUM(AW49:AW60) -> 9 | AM12: =SUM(AG12:AL12) -> 26
A13: Def x Insp. | B13: =E61 -> 3.7142857 | C13: =T61 -> 4.4285714 | D13: =AI61 -> 5.6666667 | E13: =AX61 -> 5.6363636 | F13: =F12/F11 -> 5 | Q13: Def x Insp. | S13: =S12/S11 -> 3.7142857 | T13: =T12/T11 -> 4.4285714 | U13: =U12/U11 -> 5.6666667 | W13: =W12/W11 -> 5.8888889 | Y13: =Y12/Y11 -> 4.9655172 | AF13: Def x Insp. | AG13: =AG12/AG11 -> #DIV/0! | AH13: =AH12/AH11 -> #DIV/0! | AI13: =AI12/AI11 -> 5.6666667 | AJ13: =AJ12/AJ11 -> 4.5 | AM13: =AM12/AM11 -> 5.2
A16: Compilare Solamente i Campi Grigi e Bianchi
B17: 1st quarter | Q17: 2nd quarter | AF17: 3rd quarter | AU17: 4th quarter | BJ17: Total
B18: No. Insp. | D18: Def. | E18: Def x Insp | F18: 2 | G18: 3 | H18: 4 | I18: 5 | J18: 6 | K18: 7 | L18: 8 | M18: 9 | N18: 10 | O18: 11 | P18: 12 | Q18: No. Insp. | S18: Def. | T18: Def x Insp | U18: 2 | V18: 3 | W18: 4 | X18: 5 | Y18: 6 | Z18: 7 | AA18: 8 | AB18: 9 | AC18: 10 | AD18: 11 | AE18: 12 | AF18: No. Insp. | AH18: Def. | AI18: Def x Insp | AJ18: 2 | AK18: 3 | AL18: 4 | AM18: 5 | AN18: 6 | AO18: 7 | AP18: 8 | AQ18: 9 | AR18: 10 | AS18: 11 | AT18: 12 | AU18: No. Insp. | AW18: Def. | AX18: Def x Insp | AY18: 2 | AZ18: 3 | BA18: 4 | BB18: 5 | BC18: 6 | BD18: 7 | BE18: 8 | BF18: 9 | BG18: 10 | BH18: 11 | BI18: 12 | BJ18: No. Insp. | BL18: Def. | BM18: Def x Insp
A19: ='IA-SI TANKER'!B4 -> Alpine Pembroke (Sold) | D19: =SUM(F19:P19) -> 0 | E19: =(D19/B19) -> #DIV/0! | S19: =SUM(U19:AE19) -> 0 | T19: =(S19/Q19) -> #DIV/0! | AH19: =SUM(AJ19:AT19) -> 0 | AI19: =(AH19/AF19) -> #DIV/0! | AW19: =SUM(AY19:BI19) -> 0 | AX19: =(AW19/AU19) -> #DIV/0! | BJ19: =SUM(B19+Q19+AF19+AU19) -> 0 | BL19: =SUM(D19,S19,AH19,AW19) -> 0 | BM19: =(BL19/BJ19) -> #DIV/0!
A20: ='IA-SI TANKER'!B5 -> Alpine Pioneer (Sold) | D20: =SUM(F20:P20) -> 0 | E20: =(D20/B20) -> #DIV/0! | S20: =SUM(U20:AE20) -> 0 | T20: =(S20/Q20) -> #DIV/0! | AH20: =SUM(AJ20:AT20) -> 0 | AI20: =(AH20/AF20) -> #DIV/0! | AW20: =SUM(AY20:BI20) -> 0 | AX20: =(AW20/AU20) -> #DIV/0! | BJ20: =SUM(B20+Q20+AF20+AU20) -> 0 | BL20: =SUM(D20,S20,AH20,AW20) -> 0 | BM20: =(BL20/BJ20) -> #DIV/0!
